Workbook

Sheet 0. 경영분석도구의 구조
B3: 경영분석도구 (Decision Support Tools)
D6: M1. Historical Data Analysis | K6: M2. Business Intelligence Tools
D8: 1. Parameter Table | L8: 4. 재무분석 도구
M9: (1) 손익추정/수익성/제조원가/판관비
D10: 2. 의사결정 및 경영성과 | M10: (2) 현금흐름
E11: 1-1. 경제동향 | M11: (3) 재무상태
E12: 1-2. 연도별 의사결정 | M12: (4) 재무비율
E13: 1-3. 연도별 경영성과
D15: 3. 기초분석자료 | L15: 5. 생산성 분석 도구
E16: 3-1. 경영성과추세분석 | M16: (1) HR원가 분석
E17: 3-2. 경제동향 | M17: (2) EVA 분석
E18: 3-3. GDP 변화와 판매량간의 관계 | M18: (3) 생산성 분석
E19: 3-4. 계절변화와 판매량간의 관계
E20: 3-5. R&D와 제품모델 및 판매량과의 관계
E21: 3-6. 가격변화와 판매량간의 관계 | L21: 6. 경제성 분석 도구
E22: 3-7. 광고비와 판매량간의 관계 | M22: (1) 경제성 분석
E23: 3-8. 유통매장수와 판매량간의 관계 | M23: (2) BEP 분석
E24: 3-9. 매장당 판매촉진비와 판매량간의 관계 | M24: (3) NPV 분석
E25: 3-10. 영업직원수와 판매량간의 관계 | M25: (4) IRR 분석
E26: 3-11. 영업직원기본급과 판매량간의 관계
E27: 3-12. CSR활동과 브랜드 등급 및 판매량간의 관계 | L27: 7 What-if 및 시나리오 분석
E28: 3-13. 품질개선비와 품질등급간의 관계 | M28: (1) What-if 분석
E29: 3-14. 임직원 인센티브 및 교육훈련과 직원만족도 등급간의 관계 | M29: (2) 시나리오 분석
E30: 3-15. 계절에 따른 생산량변화 및 제품모델과 제조원가간의 관계
E31: 3-16. 생산직원 인건비/품질개선비와 생산량간의 관계

Sheet 2. 의사결정 및 경영성과
B2: 1. 경제동향 | E2: ▶ 과거 3년 간의 한국, U국가, C국가 시장에 대한 경제 지표 현황을 보여주는 Table입니다.
B4: 구분 | D4: 항 목 | E4: 1차년도 1분기 | H4: 1차년도 2분기 | K4: 1차년도 3분기 | N4: 1차년도 4분기 | Q4: 2차년도 1분기 | T4: 2차년도 2분기 | W4: 2차년도 3분기 | Z4: 2차년도 4분기 | AC4: 3차년도 1분기 | AF4: 3차년도 2분기 | AI4: 3차년도 3분기 | AL4: 3차년도 4분기 | AO4: 4차년도 1분기 | AR4: 4차년도 2분기 | AU4: 4차년도 3분기 | AX4: 4차년도 4분기 | BA4: 5차년도 1분기 | BD4: 5차년도 2분기 | BG4: 5차년도 3분기 | BJ4: 5차년도 4분기
E5: 한국 | F5: U국가 | G5: C국가 | H5: 한국 | I5: U국가 | J5: C국가 | K5: 한국 | L5: U국가 | M5: C국가 | N5: 한국 | O5: U국가 | P5: C국가 | Q5: 한국 | R5: U국가 | S5: C국가 | T5: 한국 | U5: U국가 | V5: C국가 | W5: 한국 | X5: U국가 | Y5: C국가 | Z5: 한국 | AA5: U국가 | AB5: C국가 | AC5: 한국 | AD5: U국가 | AE5: C국가 | AF5: 한국 | AG5: U국가 | AH5: C국가 | AI5: 한국 | AJ5: U국가 | AK5: C국가 | AL5: 한국 | AM5: U국가 | AN5: C국가 | AO5: 한국 | AP5: U국가 | AQ5: C국가 | AR5: 한국 | AS5: U국가 | AT5: C국가 | AU5: 한국 | AV5: U국가 | AW5: C국가 | AX5: 한국 | AY5: U국가 | AZ5: C국가 | BA5: 한국 | BB5: U국가 | BC5: C국가 | BD5: 한국 | BE5: U국가 | BF5: C국가 | BG5: 한국 | BH5: U국가 | BI5: C국가 | BJ5: 한국 | BK5: U국가 | BL5: C국가
B6: 경제 지표 | D6: 1.실질 GDP(%) | E6: 88.672676 | F6: 89.344151 | G6: 82.612314 | H6: 89.155316 | I6: 93.833408 | J6: 82.572932 | K6: 88.910266 | L6: 96.447938 | M6: 82.760084 | N6: 89.525241 | O6: 98.434207 | P6: 81.361394 | Q6: 91.198832 | R6: 100.57402 | S6: 82.21909 | T6: 96.499413 | U6: 103.54891 | V6: 86.109987 | W6: 99.917649 | X6: 105.19743 | Y6: 88.185344 | Z6: 102.05693 | AA6: 104.18728 | AB6: 88.678939 | AC6: 103.70163 | AD6: 103.86805 | AE6: 92.09732 | AF6: 105.04172 | AG6: 104.15266 | AH6: 96.48398 | AI6: 103.45433 | AJ6: 102.21242 | AK6: 99.220697 | AL6: 100 | AM6: 100 | AN6: 100
D7: 2.소비자 물가지수(%) | E7: 91.3 | F7: 92.9 | G7: 90.5 | H7: 92.1 | I7: 93.4 | J7: 91.2 | K7: 92.9 | L7: 94.2 | M7: 92.1 | N7: 94.1 | O7: 95 | P7: 93 | Q7: 94.9 | R7: 95.6 | S7: 94 | T7: 95.7 | U7: 96.2 | V7: 94.9 | W7: 96.4 | X7: 97 | Y7: 95.7 | Z7: 97 | AA7: 97.5 | AB7: 96.5 | AC7: 97.7 | AD7: 98.1 | AE7: 97.3 | AF7: 98.5 | AG7: 98.8 | AH7: 98.1 | AI7: 99.2 | AJ7: 99.4 | AK7: 99 | AL7: 100 | AM7: 100 | AN7: 100
D8: 3.환율(원) | E8: 1 | F8: 1050 | G8: 199 | H8: 1 | I8: 1060 | J8: 197 | K8: 1 | L8: 1072 | M8: 195 | N8: 1 | O8: 1080 | P8: 193 | Q8: 1 | R8: 1082 | S8: 189 | T8: 1 | U8: 1083 | V8: 188 | W8: 1 | X8: 1090 | Y8: 187 | Z8: 1 | AA8: 1098 | AB8: 185 | AC8: 1 | AD8: 1104 | AE8: 179 | AF8: 1 | AG8: 1106 | AH8: 176 | AI8: 1 | AJ8: 1102 | AK8: 175.3 | AL8: 1 | AM8: 1100 | AN8: 175
D9: 4.주가지수(P) | E9: 92.478926 | F9: 97.676668 | G9: 80.450834 | H9: 92.525673 | I9: 97.426054 | J9: 80.605572 | K9: 92.466218 | L9: 98.972392 | M9: 78.558335 | N9: 95.956959 | O9: 101.16438 | P9: 77.180368 | Q9: 98.446735 | R9: 105.57032 | S9: 81.510447 | T9: 102.27761 | U9: 106.73539 | V9: 83.215042 | W9: 106.16653 | X9: 107.93546 | Y9: 85.31187 | Z9: 106.83231 | AA9: 106.76769 | AB9: 88.608966 | AC9: 109.42323 | AD9: 106.94361 | AE9: 90.37308 | AF9: 107.676 | AG9: 104.81533 | AH9: 94.640839 | AI9: 103.90371 | AJ9: 103.81628 | AK9: 96.219402 | AL9: 100 | AM9: 100 | AN9: 100
D10: 5.CD 이자율(%) | E10: 5.8452487 | F10: 4.2332802 | G10: 6.2629669 | H10: 5.9867723 | I10: 4.3285754 | J10: 6.6274119 | K10: 6.5688036 | L10: 4.5450851 | M10: 6.9181135 | N10: 5.9189687 | O10: 4.086136 | P10: 7.1236407 | Q10: 5.768574 | R10: 4.0470215 | S10: 6.6560981 | T10: 5.8490077 | U10: 4.2041991 | V10: 6.4201678 | W10: 5.5047004 | X10: 4.0947785 | Y10: 6.573957 | Z10: 5.7958433 | AA10: 4.0753836 | AB10: 6.4378337 | AC10: 5.9589883 | AD10: 4.0979644 | AE10: 6.5701987 | AF10: 5.4698006 | AG10: 4.064525 | AH10: 6.7519894 | AI10: 5.7786355 | AJ10: 4.3052193 | AK10: 7.1188022 | AL10: 6.8963643 | AM10: 4.4640199 | AN10: 7.0867353
B12: 2. 연도별 의사결정 | E12: ▶ 과거 3년 간 경영 의사결정에 대한 현황을 보여주는 Table입니다.
B14: 역할 | C14: 분류 | D14: 항목 | E14: 1차년도 1분기 | H14: 1차년도 2분기 | K14: 1차년도 3분기 | N14: 1차년도 4분기 | Q14: 2차년도 1분기 | T14: 2차년도 2분기 | W14: 2차년도 3분기 | Z14: 2차년도 4분기 | AC14: 3차년도 1분기 | AF14: 3차년도 2분기 | AI14: 3차년도 3분기 | AL14: 3차년도 4분기 | AO14: 4차년도1분기 | AR14: 4차년도 2분기 | AU14: 4차년도3분기 | AX14: 4차년도 4분기 | BA14: 5차년도 1분기 | BD14: 5차년도 2분기 | BG14: 5차년도 3분기 | BJ14: 5차년도 4분기
E15: 한국 | F15: U국가 | G15: C국가 | H15: 한국 | I15: U국가 | J15: C국가 | K15: 한국 | L15: U국가 | M15: C국가 | N15: 한국 | O15: U국가 | P15: C국가 | Q15: 한국 | R15: U국가 | S15: C국가 | T15: 한국 | U15: U국가 | V15: C국가 | W15: 한국 | X15: U국가 | Y15: C국가 | Z15: 한국 | AA15: U국가 | AB15: C국가 | AC15: 한국 | AD15: U국가 | AE15: C국가 | AF15: 한국 | AG15: U국가 | AH15: C국가 | AI15: 한국 | AJ15: U국가 | AK15: C국가 | AL15: 한국 | AM15: U국가 | AN15: C국가 | AO15: 한국 | AP15: U국가 | AQ15: C국가 | AR15: 한국 | AS15: U국가 | AT15: C국가 | AU15: 한국 | AV15: U국가 | AW15: C국가 | AX15: 한국 | AY15: U국가 | AZ15: C국가 | BA15: 한국 | BB15: U국가 | BC15: C국가 | BD15: 한국 | BE15: U국가 | BF15: C국가 | BG15: 한국 | BH15: U국가 | BI15: C국가 | BJ15: 한국 | BK15: U국가 | BL15: C국가
B16: CEO | C16: 기술개발 및 상생 | D16: 1. CSR 활동비 | E16: 0 | H16: 0 | K16: 0 | N16: 100000000 | Q16: 150000000 | T16: 250000000 | W16: 280000000 | Z16: 350000000 | AC16: 420000000 | AF16: 460000000 | AI16: 480000000 | AL16: 500000000
D17: 2. 임직원 인센티브 | E17: 0 | H17: 0 | K17: 200000000 | N17: 300000000 | Q17: 500000000 | T17: 900000000 | W17: 950000000 | Z17: 1000000000 | AC17: 1100000000 | AF17: 1350000000 | AI17: 1400000000 | AL17: 1500000000
B18: CMO | C18: 제품 | D18: 1. 판매제품 모델 | E18: 1 | H18: 1 | K18: 1 | N18: 1 | Q18: 2 | T18: 2 | W18: 2 | Z18: 2 | AC18: 3 | AF18: 3 | AI18: 4 | AL18: 4
C19: 발주 | D19: 2. 영업본부 공장 발주량 | E19: 40000 | F19: 30000 | G19: 10000 | H19: 45000 | I19: 30000 | J19: 10000 | K19: 45000 | L19: 35000 | M19: 15000 | N19: 45000 | O19: 40000 | P19: 15000 | Q19: 40000 | R19: 35000 | S19: 15000 | T19: 45000 | U19: 40000 | V19: 15000 | W19: 65000 | X19: 40000 | Y19: 15000 | Z19: 65000 | AA19: 40000 | AB19: 15000 | AC19: 50000 | AD19: 35000 | AE19: 15000 | AF19: 55000 | AG19: 40000 | AH19: 25000 | AI19: 60000 | AJ19: 35000 | AK19: 28000 | AL19: 60000 | AM19: 30000 | AN19: 30000
C20: 가격 | D20: 3. 판매가격 | E20: 460000 | F20: 505 | G20: 2400 | H20: 470000 | I20: 512 | J20: 2450 | K20: 475000 | L20: 515 | M20: 2500 | N20: 480000 | O20: 520 | P20: 2650 | Q20: 525000 | R20: 550 | S20: 2900 | T20: 530000 | U20: 555 | V20: 2950 | W20: 540000 | X20: 560 | Y20: 3000 | Z20: 590000 | AA20: 595 | AB20: 3250 | AC20: 600000 | AD20: 600 | AE20: 3300 | AF20: 610000 | AG20: 615 | AH20: 3400 | AI20: 670000 | AJ20: 635 | AK20: 3700 | AL20: 680000 | AM20: 640 | AN20: 3800
C21: 유통 | D21: 4. 유통매장 신설(+) 및 폐쇄(-) | E21: 3 | F21: 1 | G21: 1 | H21: 2 | I21: 1 | J21: 1 | K21: 2 | L21: 1 | M21: 1 | N21: 3 | O21: 1 | P21: 1 | Q21: 4 | R21: 1 | S21: 1 | T21: 2 | U21: 2 | V21: 2 | W21: 2 | X21: 1 | Y21: 1 | Z21: 2 | AA21: 1 | AB21: 1 | AC21: 2 | AD21: 1 | AE21: 1 | AF21: 2 | AG21: 1 | AH21: 1 | AI21: 1 | AJ21: 2 | AK21: 1 | AL21: 5 | AM21: 2 | AN21: 3
C22: 판촉 | D22: 5. 광고비 | E22: 1500000000 | F22: 800000 | G22: 5500000 | H22: 1550000000 | I22: 900000 | J22: 6000000 | K22: 1700000000 | L22: 1050000 | M22: 6300000 | N22: 1750000000 | O22: 1055000 | P22: 6500000 | Q22: 1850000000 | R22: 1100000 | S22: 7000000 | T22: 2000000000 | U22: 1150000 | V22: 9000000 | W22: 2100000000 | X22: 1200000 | Y22: 9500000 | Z22: 2500000000 | AA22: 1550000 | AB22: 10000000 | AC22: 2550000000 | AD22: 1600000 | AE22: 10500000 | AF22: 2600000000 | AG22: 1700000 | AH22: 11000000 | AI22: 3000000000 | AJ22: 1800000 | AK22: 11500000 | AL22: 3200000000 | AM22: 1900000 | AN22: 12000000
D23: 6. 판매촉진비(매장당) | E23: 25000000 | F23: 25000 | G23: 80000 | H23: 26000000 | I23: 26500 | J23: 95000 | K23: 27500000 | L23: 26000 | M23: 100000 | N23: 28000000 | O23: 29000 | P23: 105000 | Q23: 31000000 | R23: 30500 | S23: 115000 | T23: 32000000 | U23: 31000 | V23: 120000 | W23: 33000000 | X23: 34000 | Y23: 125000 | Z23: 36500000 | AA23: 35000 | AB23: 130000 | AC23: 37000000 | AD23: 37000 | AE23: 135000 | AF23: 38000000 | AG23: 38000 | AH23: 140000 | AI23: 39000000 | AJ23: 39000 | AK23: 145000 | AL23: 40000000 | AM23: 40000 | AN23: 150000
B24: COO | C24: 정규생산라인 생산 계획 | D24: 1. 가동 생산라인 수 | E24: 4 | F24: 0 | G24: 0 | H24: 4 | I24: 0 | J24: 0 | K24: 5 | L24: 0 | M24: 0 | N24: 5 | O24: 0 | P24: 0 | Q24: 4 | R24: 0 | S24: 0 | T24: 5 | U24: 0 | V24: 0 | W24: 6 | X24: 0 | Y24: 0 | Z24: 6 | AA24: 0 | AB24: 0 | AC24: 6 | AD24: 0 | AE24: 0 | AF24: 6 | AG24: 0 | AH24: 0 | AI24: 6 | AJ24: 0 | AK24: 0 | AL24: 6 | AM24: 0 | AN24: 0
D25: 2. 조업중지 생산라인 수 | E25: 2 | F25: 0 | G25: 0 | H25: 2 | I25: 0 | J25: 0 | K25: 1 | L25: 0 | M25: 0 | N25: 1 | O25: 0 | P25: 0 | Q25: 2 | R25: 0 | S25: 0 | T25: 1 | U25: 0 | V25: 0 | W25: 0 | X25: 0 | Y25: 0 | Z25: 0 | AA25: 0 | AB25: 0 | AC25: 0 | AD25: 0 | AE25: 0 | AF25: 0 | AG25: 0 | AH25: 0 | AI25: 0 | AJ25: 0 | AK25: 0 | AL25: 0 | AM25: 0 | AN25: 0
D26: 3. 폐쇄 생산라인 수 | E26: 0 | F26: 0 | G26: 0 | H26: 0 | I26: 0 | J26: 0 | K26: 0 | L26: 0 | M26: 0 | N26: 0 | O26: 0 | P26: 0 | R26: 0 | S26: 0 | U26: 0 | V26: 0 | W26: 0 | X26: 0 | Y26: 0 | Z26: 0 | AA26: 0 | AB26: 0 | AC26: 0 | AD26: 0 | AE26: 0 | AF26: 0 | AG26: 0 | AH26: 0 | AI26: 0 | AJ26: 0 | AK26: 0 | AL26: 0 | AM26: 0 | AN26: 0
D27: 4. 생산라인 작업시간 | E27: 40 | F27: 0 | G27: 0 | H27: 40 | I27: 0 | J27: 0 | K27: 40 | L27: 0 | M27: 0 | N27: 40 | O27: 0 | P27: 0 | Q27: 40 | R27: 0 | S27: 0 | T27: 44 | U27: 0 | V27: 0 | W27: 44 | X27: 0 | Y27: 0 | Z27: 48 | AA27: 0 | AB27: 0 | AC27: 40 | AD27: 0 | AE27: 0 | AF27: 44 | AG27: 0 | AH27: 0 | AI27: 44 | AJ27: 0 | AK27: 0 | AL27: 48 | AM27: 0 | AN27: 0
C28: 2교대 생산라인 생산 계획 | D28: 5. 가동 생산라인 수 | E28: 0 | F28: 0 | G28: 0 | H28: 0 | I28: 0 | J28: 0 | K28: 0 | L28: 0 | M28: 0 | N28: 0 | O28: 0 | P28: 0 | Q28: 0 | R28: 0 | S28: 0 | T28: 0 | U28: 0 | V28: 0 | W28: 0 | X28: 0 | Y28: 0 | Z28: 0 | AA28: 0 | AB28: 0 | AC28: 0 | AD28: 0 | AE28: 0 | AF28: 0 | AG28: 0 | AH28: 0 | AI28: 0 | AJ28: 0 | AK28: 0 | AL28: 0 | AM28: 0 | AN28: 0
D29: 6. 조업중지 생산라인 수 | E29: 0 | F29: 0 | G29: 0 | H29: 0 | I29: 0 | J29: 0 | K29: 0 | L29: 0 | M29: 0 | N29: 0 | O29: 0 | P29: 0 | Q29: 0 | R29: 0 | S29: 0 | T29: 0 | U29: 0 | V29: 0 | W29: 0 | X29: 0 | Y29: 0 | Z29: 0 | AA29: 0 | AB29: 0 | AC29: 0 | AD29: 0 | AE29: 0 | AF29: 0 | AG29: 0 | AH29: 0 | AI29: 0 | AJ29: 0 | AK29: 0 | AL29: 0 | AM29: 0 | AN29: 0
D30: 7. 폐쇄 생산라인 수 | E30: 0 | F30: 0 | G30: 0 | H30: 0 | I30: 0 | J30: 0 | K30: 0 | L30: 0 | M30: 0 | N30: 0 | O30: 0 | P30: 0 | Q30: 0 | R30: 0 | S30: 0 | T30: 0 | U30: 0 | V30: 0 | W30: 0 | X30: 0 | Y30: 0 | Z30: 0 | AA30: 0 | AB30: 0 | AC30: 0 | AD30: 0 | AE30: 0 | AF30: 0 | AG30: 0 | AH30: 0 | AI30: 0 | AJ30: 0 | AK30: 0 | AL30: 0 | AM30: 0 | AN30: 0
D31: 8. 생산라인 작업시간 | E31: 0 | F31: 0 | G31: 0 | H31: 0 | I31: 0 | J31: 0 | K31: 0 | L31: 0 | M31: 0 | N31: 0 | O31: 0 | P31: 0 | Q31: 0 | R31: 0 | S31: 0 | T31: 0 | U31: 0 | V31: 0 | W31: 0 | X31: 0 | Y31: 0 | Z31: 0 | AA31: 0 | AB31: 0 | AC31: 0 | AD31: 0 | AE31: 0 | AF31: 0 | AG31: 0 | AH31: 0 | AI31: 0 | AJ31: 0 | AK31: 0 | AL31: 0 | AM31: 0 | AN31: 0
C32: 구매 | D32: 9. 부품 구매량 | E32: =E72 -> 83166 | F32: =F72 -> 0 | G32: =G72 -> 0 | H32: =H72 -> 86561 | I32: =I72 -> 0 | J32: =J72 -> 0 | K32: =K72 -> 98841 | L32: =L72 -> 0 | ... AH32: =AH72 -> 0 | AI32: 130020 | AJ32: 0 | AK32: 0 | AL32: 136080 | AM32: 0 | AN32: 0
C33: 생산 효율성 | D33: 10. 설비관리 보전비(라인 당) | E33: 20000000 | F33: =F73 -> 0 | G33: =G73 -> 0 | H33: 25000000 | I33: =I73 -> 0 | J33: =J73 -> 0 | K33: 28000000 | L33: =L73 -> 0 | M33: =M73 -> 0 | N33: 30000000 | O33: =O73 -> 0 | P33: =P73 -> 0 | Q33: 35000000 | R33: 0 | S33: 0 | T33: 37000000 | U33: 0 | V33: 0 | W33: 40000000 | X33: 0 | Y33: 0 | Z33: 42000000 | AA33: 0 | AB33: 0 | AC33: 43000000 | AD33: 0 | AE33: 0 | AF33: 45000000 | AG33: 0 | AH33: 0 | AI33: 48000000 | AJ33: 0 | AK33: 0 | AL33: 50000000 | AM33: 0 | AN33: 0
C34: 생산능력 조정 | D34: 11. 2교대생산라인 신설(1분기 소요) | E34: 0 | F34: 0 | G34: 0 | H34: 0 | I34: 0 | J34: 0 | K34: 0 | L34: 0 | M34: 0 | N34: 0 | O34: 0 | P34: 0 | Q34: 0 | R34: 0 | S34: 0 | T34: 0 | U34: 0 | V34: 0 | W34: 0 | X34: 0 | Y34: 0 | Z34: 0 | AA34: 0 | AB34: 0 | AC34: 0 | AD34: 0 | AE34: 0 | AF34: 0 | AG34: 0 | AH34: 0 | AI34: 0 | AJ34: 0 | AK34: 0 | AL34: 0 | AM34: 0 | AN34: 0
D35: 12. 정규생산라인 신설(2분기 소요) | E35: 0 | F35: 0 | G35: 0 | H35: 0 | I35: 0 | J35: 0 | K35: 0 | L35: 0 | M35: 0 | N35: 0 | O35: 0 | P35: 0 | Q35: 0 | R35: 0 | S35: 0 | T35: 0 | U35: 0 | V35: 0 | W35: 0 | X35: 0 | Y35: 0 | Z35: 0 | AA35: 0 | AB35: 0 | AC35: 0 | AD35: 0 | AE35: 0 | AF35: 0 | AG35: 0 | AH35: 0 | AI35: 0 | AJ35: 0 | AK35: 0 | AL35: 0 | AM35: 0 | AN35: 0
D36: 13. 공장신설(2분기 소요)및 폐쇄 | E36: 0 | F36: 0 | G36: 0 | H36: 0 | I36: 0 | J36: 0 | K36: 0 | L36: 0 | M36: 0 | N36: 0 | O36: 0 | P36: 0 | Q36: 0 | R36: 0 | S36: 0 | T36: 0 | U36: 0 | V36: 0 | W36: 0 | X36: 0 | Y36: 0 | Z36: 0 | AA36: 0 | AB36: 0 | AC36: 0 | AD36: 0 | AE36: 0 | AF36: 0 | AG36: 0 | AH36: 0 | AI36: 0 | AJ36: 0 | AK36: 0 | AL36: 0 | AM36: 0 | AN36: 0
B37: CTO | C37: R&D 기술개발 | D37: 1. 선행기술R&D투자비 | E37: 1120000000 | H37: 1.4e+09 | K37: 1.568e+09 | N37: 1.736e+09 | Q37: 1.848e+09 | T37: 2.044e+09 | W37: 2184000000 | Z37: 2296000000 | AC37: 2464000000 | AF37: 2.576e+09 | AI37: 2.688e+09 | AL37: 2.8e+09
D38: 2. 양산R&D투자비 | E38: 640000000 | H38: 650000000 | K38: 750000000 | N38: 810000000 | Q38: 920000000 | T38: 980000000 | W38: 1000000000 | Z38: 1040000000 | AC38: 1080000000 | AF38: 1100000000 | AI38: 1160000000 | AL38: 1200000000
C39: R&D 인력관리 | D39: 3. R&D인원수 채용(+) 및 해고(-) | E39: 10 | H39: 9 | K39: 8 | N39: 8 | Q39: 6 | T39: 6 | W39: 6 | Z39: 5 | AC39: 4 | AF39: 4 | AI39: 5 | AL39: 5
D40: 4. R&D고급인력 (스카우트 및 해고) | E40: 0 | H40: 0 | K40: 0 | N40: 4 | Q40: 5 | T40: 7 | W40: 7 | Z40: 6 | AC40: 7 | AF40: 7 | AI40: 5 | AL40: 3
D41: 5. R&D 인건비 | H41: =H44/80000000*90000000 -> 6277500 | K41: =K44/AL44*AL41 -> 6378750 | N41: =N44/AL44*AL41 -> 6480000 | Q41: =Q44/AL44*AL41 -> 6682500 | T41: =T44/AL44*AL41 -> 6986250 | W41: =W44/AL44*AL41 -> 7188750 | Z41: =Z44/AL44*AL41 -> 7330500 | AC41: =AC44/AL44*AL41 -> 7553250 | AF41: =AF44/AL44*AL41 -> 7695000 | AI41: =AI44/AL44*AL41 -> 8059500 | AL41: 9000000
B42: CHO | C42: 인력 관리 | D42: 1. 영업직원 채용(+) 및 해고(-) | E42: 28 | F42: 8 | G42: 9 | H42: 20 | I42: 10 | J42: 12 | K42: 30 | L42: 13 | M42: 17 | N42: 35 | O42: 16 | P42: 18 | Q42: 29 | R42: 15 | S42: 20 | T42: 32 | U42: 20 | V42: 26 | W42: 31 | X42: 19 | Y42: 20 | Z42: 37 | AA42: 10 | AB42: 15 | AC42: 25 | AD42: 13 | AE42: 15 | AF42: 28 | AG42: 12 | AH42: 10 | AI42: 32 | AJ42: 16 | AK42: 17 | AL42: 35 | AM42: 17 | AN42: 22
D43: 2. 디지털마케팅 고급인력(스카우트 및 해고) | E43: 0 | H43: 0 | K43: 0 | N43: 0 | Q43: 2 | T43: 3 | W43: 4 | Z43: 4 | AC43: 4 | AF43: 4 | AI43: 7 | AL43: 5
C44: 영업직원 임금과 보상 | D44: 3. 영업직원 기본급(인당) | E44: 5400000 | F44: 7884 | G44: 16200 | H44: 5580000 | I44: 8010 | J44: 16560 | K44: 5670000 | L44: 8100 | M44: 17640 | N44: 5760000 | O44: 8406 | P44: 18900 | Q44: 5940000 | R44: 8460 | S44: 19800 | T44: 6210000 | U44: 8550 | V44: 20700 | W44: 6390000 | X44: 8676 | Y44: 22140 | Z44: 6516000 | AA44: 8730 | AB44: 23040 | AC44: 6714000 | AD44: 8937 | AE44: 23760 | AF44: 6840000 | AG44: 8964 | AH44: 25200 | AI44: 7164000 | AJ44: 8982 | AK44: 26100 | AL44: 8000000 | AM44: 10000 | AN44: 30000
...

Sheet 3. 기초 분석 자료
B2: ▶ 경영의사결정 변수들과 경영성과 지표들간의 상관 관계를 비교한 기초 분석 자료입니다. ▶ 매 분기 시스템에서 새로운 성과가 출력되면, 입력하면서 관리해야 합니다. (자동으로 연결되지 않음)
A4: 1. 경영성과 추세 분석
B5: 연도 | C5: 1차년도 | G5: 2차년도 | K5: 3차년도 | O5: 4차년도 | S5: 5차년도
B6: 분기 | C6: 1Q | D6: 2Q | E6: 3Q | F6: 4Q | G6: 1Q | H6: 2Q | I6: 3Q | J6: 4Q | K6: 1Q | L6: 2Q | M6: 3Q | N6: 4Q | O6: 1Q | P6: 2Q | Q6: 3Q | R6: 4Q | S6: 1Q | T6: 2Q | U6: 3Q | V6: 4Q
B7: 매출액 | C7: ='2. 의사결정 및 경영성과'!E62 -> 33151687950 | D7: ='2. 의사결정 및 경영성과'!H62 -> 47523605420 | E7: ='2. 의사결정 및 경영성과'!K62 -> 46225732120 | F7: ='2. 의사결정 및 경영성과'!N62 -> 54564429150 | G7: ='2. 의사결정 및 경영성과'!Q62 -> 43306982400 | H7: ='2. 의사결정 및 경영성과'!T62 -> 63579142610 | I7: ='2. 의사결정 및 경영성과'!W62 -> 61613796600 | J7: ='2. 의사결정 및 경영성과'!Z62 -> 82256656730 | K7: ='2. 의사결정 및 경영성과'!AC62 -> 71903606400 | L7: ='2. 의사결정 및 경영성과'!AF62 -> 90583806230 | M7: ='2. 의사결정 및 경영성과'!AI62 -> 88839553740 | N7: ='2. 의사결정 및 경영성과'!AL62 -> 88631620000 | O7: ='2. 의사결정 및 경영성과'!AO62 -> 0 | P7: ='2. 의사결정 및 경영성과'!AR62 -> 0 | Q7: ='2. 의사결정 및 경영성과'!AU62 -> 0 | R7: ='2. 의사결정 및 경영성과'!AX62 -> 0 | S7: ='2. 의사결정 및 경영성과'!BA62 -> 0 | T7: ='2. 의사결정 및 경영성과'!BD62 -> 0 | U7: ='2. 의사결정 및 경영성과'!BG62 -> 0 | V7: ='2. 의사결정 및 경영성과'!BJ62 -> 0
B8: 당기순이익 | C8: ='2. 의사결정 및 경영성과'!E64 -> -364768440 | D8: ='2. 의사결정 및 경영성과'!H64 -> 3059295121 | E8: ='2. 의사결정 및 경영성과'!K64 -> 2984019702 | F8: ='2. 의사결정 및 경영성과'!N64 -> 4654162032 | G8: ='2. 의사결정 및 경영성과'!Q64 -> 3456071751 | H8: ='2. 의사결정 및 경영성과'!T64 -> 5911264883 | I8: ='2. 의사결정 및 경영성과'!W64 -> 4343778682 | J8: ='2. 의사결정 및 경영성과'!Z64 -> 3075618589 | K8: ='2. 의사결정 및 경영성과'!AC64 -> 2689559000 | L8: ='2. 의사결정 및 경영성과'!AF64 -> 4870881691 | M8: ='2. 의사결정 및 경영성과'!AI64 -> 4969523434 | N8: ='2. 의사결정 및 경영성과'!AL64 -> 4119883657 | O8: ='2. 의사결정 및 경영성과'!AO64 -> 0 | P8: ='2. 의사결정 및 경영성과'!AR64 -> 0 | Q8: ='2. 의사결정 및 경영성과'!AU64 -> 0 | R8: ='2. 의사결정 및 경영성과'!AX64 -> 0 | S8: ='2. 의사결정 및 경영성과'!BA64 -> 0 | T8: ='2. 의사결정 및 경영성과'!BD64 -> 0 | U8: ='2. 의사결정 및 경영성과'!BG64 -> 0 | V8: ='2. 의사결정 및 경영성과'!BJ64 -> 0
B9: 신용등급 | C9: ='2. 의사결정 및 경영성과'!E67 -> 7 | D9: ='2. 의사결정 및 경영성과'!H67 -> 4 | E9: ='2. 의사결정 및 경영성과'!K67 -> 7 | F9: ='2. 의사결정 및 경영성과'!N67 -> 3 | G9: ='2. 의사결정 및 경영성과'!Q67 -> 7 | H9: ='2. 의사결정 및 경영성과'!T67 -> 3 | I9: ='2. 의사결정 및 경영성과'!W67 -> 3 | J9: ='2. 의사결정 및 경영성과'!Z67 -> 2 | K9: ='2. 의사결정 및 경영성과'!AC67 -> 4 | L9: ='2. 의사결정 및 경영성과'!AF67 -> 2 | M9: ='2. 의사결정 및 경영성과'!AI67 -> 3 | N9: ='2. 의사결정 및 경영성과'!AL67 -> 4 | O9: ='2. 의사결정 및 경영성과'!AO67 -> 0 | P9: ='2. 의사결정 및 경영성과'!AR67 -> 0 | Q9: ='2. 의사결정 및 경영성과'!AU67 -> 0 | R9: ='2. 의사결정 및 경영성과'!AX67 -> 0 | S9: ='2. 의사결정 및 경영성과'!BA67 -> 0 | T9: ='2. 의사결정 및 경영성과'!BD67 -> 0 | U9: ='2. 의사결정 및 경영성과'!BG67 -> 0 | V9: ='2. 의사결정 및 경영성과'!BJ67 -> 0
B10: 주가 | C10: ='2. 의사결정 및 경영성과'!E65 -> 4583 | D10: ='2. 의사결정 및 경영성과'!H65 -> 5252 | E10: ='2. 의사결정 및 경영성과'!K65 -> 5056 | F10: ='2. 의사결정 및 경영성과'!N65 -> 6097 | G10: ='2. 의사결정 및 경영성과'!Q65 -> 4878 | H10: ='2. 의사결정 및 경영성과'!T65 -> 6389 | I10: ='2. 의사결정 및 경영성과'!W65 -> 6251 | J10: ='2. 의사결정 및 경영성과'!Z65 -> 6547 | K10: ='2. 의사결정 및 경영성과'!AC65 -> 5724 | L10: ='2. 의사결정 및 경영성과'!AF65 -> 6839 | M10: ='2. 의사결정 및 경영성과'!AI65 -> 6142 | N10: ='2. 의사결정 및 경영성과'!AL65 -> 5774 | O10: ='2. 의사결정 및 경영성과'!AO65 -> 0 | P10: ='2. 의사결정 및 경영성과'!AR65 -> 0 | Q10: ='2. 의사결정 및 경영성과'!AU65 -> 0 | R10: ='2. 의사결정 및 경영성과'!AX65 -> 0 | S10: ='2. 의사결정 및 경영성과'!BA65 -> 0 | T10: ='2. 의사결정 및 경영성과'!BD65 -> 0 | U10: ='2. 의사결정 및 경영성과'!BG65 -> 0 | V10: ='2. 의사결정 및 경영성과'!BJ65 -> 0
B11: 기말현금 | C11: ='2. 의사결정 및 경영성과'!E88 -> 2.8028767e+09 | D11: ='2. 의사결정 및 경영성과'!H88 -> 3.5180882e+09 | E11: ='2. 의사결정 및 경영성과'!K88 -> 6.3331296e+09 | F11: ='2. 의사결정 및 경영성과'!N88 -> 9.2067353e+09 | G11: ='2. 의사결정 및 경영성과'!Q88 -> 4.7604925e+09 | H11: ='2. 의사결정 및 경영성과'!T88 -> 3.5277335e+09 | I11: ='2. 의사결정 및 경영성과'!W88 -> 6.768786e+09 | J11: ='2. 의사결정 및 경영성과'!Z88 -> 4.5283883e+09 | K11: ='2. 의사결정 및 경영성과'!AC88 -> 8.6498001e+09 | L11: ='2. 의사결정 및 경영성과'!AF88 -> 1.1209512e+10 | M11: ='2. 의사결정 및 경영성과'!AI88 -> 1.4218478e+10 | N11: ='2. 의사결정 및 경영성과'!AL88 -> 15025724183 | O11: ='2. 의사결정 및 경영성과'!AO88 -> 0 | P11: ='2. 의사결정 및 경영성과'!AR88 -> 0 | Q11: ='2. 의사결정 및 경영성과'!AU88 -> 0 | R11: ='2. 의사결정 및 경영성과'!AX88 -> 0 | S11: ='2. 의사결정 및 경영성과'!BA88 -> 0 | T11: ='2. 의사결정 및 경영성과'!BD88 -> 0 | U11: ='2. 의사결정 및 경영성과'!BG88 -> 0 | V11: ='2. 의사결정 및 경영성과'!BJ88 -> 0
A35: 2. 경제 동향
A36: 경제지표 | B36: 영업본부 | C36: 1차년도 | G36: 2차년도 | K36: 3차년도 | O36: 4차년도 | S36: 5차년도
C37: 1Q | D37: 2Q | E37: 3Q | F37: 4Q | G37: 1Q | H37: 2Q | I37: 3Q | J37: 4Q | K37: 1Q | L37: 2Q | M37: 3Q | N37: 4Q | O37: 1Q | P37: 2Q | Q37: 3Q | R37: 4Q | S37: 1Q | T37: 2Q | U37: 3Q | V37: 4Q
A38: 실질 GDP | B38: 한국 | C38: ='2. 의사결정 및 경영성과'!E6 -> 88.672676 | D38: ='2. 의사결정 및 경영성과'!H6 -> 89.155316 | E38: ='2. 의사결정 및 경영성과'!K6 -> 88.910266 | F38: ='2. 의사결정 및 경영성과'!N6 -> 89.525241 | G38: ='2. 의사결정 및 경영성과'!Q6 -> 91.198832 | H38: ='2. 의사결정 및 경영성과'!T6 -> 96.499413 | I38: ='2. 의사결정 및 경영성과'!W6 -> 99.917649 | J38: ='2. 의사결정 및 경영성과'!Z6 -> 102.05693 | K38: ='2. 의사결정 및 경영성과'!AC6 -> 103.70163 | L38: ='2. 의사결정 및 경영성과'!AF6 -> 105.04172 | M38: ='2. 의사결정 및 경영성과'!AI6 -> 103.45433 | N38: ='2. 의사결정 및 경영성과'!AL6 -> 100 | O38: ='2. 의사결정 및 경영성과'!AO6 -> 0 | P38: ='2. 의사결정 및 경영성과'!AR6 -> 0 | Q38: ='2. 의사결정 및 경영성과'!AU6 -> 0 | R38: ='2. 의사결정 및 경영성과'!AX6 -> 0 | S38: ='2. 의사결정 및 경영성과'!BA6 -> 0 | T38: ='2. 의사결정 및 경영성과'!BD6 -> 0 | U38: ='2. 의사결정 및 경영성과'!BG6 -> 0 | V38: ='2. 의사결정 및 경영성과'!BJ6 -> 0
B39: U국가 | C39: ='2. 의사결정 및 경영성과'!F6 -> 89.344151 | D39: ='2. 의사결정 및 경영성과'!I6 -> 93.833408 | E39: ='2. 의사결정 및 경영성과'!L6 -> 96.447938 | F39: ='2. 의사결정 및 경영성과'!O6 -> 98.434207 | G39: ='2. 의사결정 및 경영성과'!R6 -> 100.57402 | H39: ='2. 의사결정 및 경영성과'!U6 -> 103.54891 | I39: ='2. 의사결정 및 경영성과'!X6 -> 105.19743 | J39: ='2. 의사결정 및 경영성과'!AA6 -> 104.18728 | K39: ='2. 의사결정 및 경영성과'!AD6 -> 103.86805 | L39: ='2. 의사결정 및 경영성과'!AG6 -> 104.15266 | M39: ='2. 의사결정 및 경영성과'!AJ6 -> 102.21242 | N39: ='2. 의사결정 및 경영성과'!AM6 -> 100 | O39: ='2. 의사결정 및 경영성과'!AP6 -> 0 | P39: ='2. 의사결정 및 경영성과'!AS6 -> 0 | Q39: ='2. 의사결정 및 경영성과'!AV6 -> 0 | R39: ='2. 의사결정 및 경영성과'!AY6 -> 0 | S39: ='2. 의사결정 및 경영성과'!BB6 -> 0 | T39: ='2. 의사결정 및 경영성과'!BE6 -> 0 | U39: ='2. 의사결정 및 경영성과'!BH6 -> 0 | V39: ='2. 의사결정 및 경영성과'!BK6 -> 0
B40: C국가 | C40: ='2. 의사결정 및 경영성과'!G6 -> 82.612314 | D40: ='2. 의사결정 및 경영성과'!J6 -> 82.572932 | E40: ='2. 의사결정 및 경영성과'!M6 -> 82.760084 | F40: ='2. 의사결정 및 경영성과'!P6 -> 81.361394 | G40: ='2. 의사결정 및 경영성과'!S6 -> 82.21909 | H40: ='2. 의사결정 및 경영성과'!V6 -> 86.109987 | I40: ='2. 의사결정 및 경영성과'!Y6 -> 88.185344 | J40: ='2. 의사결정 및 경영성과'!AB6 -> 88.678939 | K40: ='2. 의사결정 및 경영성과'!AE6 -> 92.09732 | L40: ='2. 의사결정 및 경영성과'!AH6 -> 96.48398 | M40: ='2. 의사결정 및 경영성과'!AK6 -> 99.220697 | N40: ='2. 의사결정 및 경영성과'!AN6 -> 100 | O40: ='2. 의사결정 및 경영성과'!AQ6 -> 0 | P40: ='2. 의사결정 및 경영성과'!AT6 -> 0 | Q40: ='2. 의사결정 및 경영성과'!AW6 -> 0 | R40: ='2. 의사결정 및 경영성과'!AZ6 -> 0 | S40: ='2. 의사결정 및 경영성과'!BC6 -> 0 | T40: ='2. 의사결정 및 경영성과'!BF6 -> 0 | U40: ='2. 의사결정 및 경영성과'!BI6 -> 0 | V40: ='2. 의사결정 및 경영성과'!BL6 -> 0
A41: 소비자 물가지수 | B41: 한국 | C41: ='2. 의사결정 및 경영성과'!E7 -> 91.3 | D41: ='2. 의사결정 및 경영성과'!H7 -> 92.1 | E41: ='2. 의사결정 및 경영성과'!K7 -> 92.9 | F41: ='2. 의사결정 및 경영성과'!N7 -> 94.1 | G41: ='2. 의사결정 및 경영성과'!Q7 -> 94.9 | H41: ='2. 의사결정 및 경영성과'!T7 -> 95.7 | I41: ='2. 의사결정 및 경영성과'!W7 -> 96.4 | J41: ='2. 의사결정 및 경영성과'!Z7 -> 97 | K41: ='2. 의사결정 및 경영성과'!AC7 -> 97.7 | L41: ='2. 의사결정 및 경영성과'!AF7 -> 98.5 | M41: ='2. 의사결정 및 경영성과'!AI7 -> 99.2 | N41: ='2. 의사결정 및 경영성과'!AL7 -> 100 | O41: ='2. 의사결정 및 경영성과'!AO7 -> 0 | P41: ='2. 의사결정 및 경영성과'!AR7 -> 0 | Q41: ='2. 의사결정 및 경영성과'!AU7 -> 0 | R41: ='2. 의사결정 및 경영성과'!AX7 -> 0 | S41: ='2. 의사결정 및 경영성과'!BA7 -> 0 | T41: ='2. 의사결정 및 경영성과'!BD7 -> 0 | U41: ='2. 의사결정 및 경영성과'!BG7 -> 0 | V41: ='2. 의사결정 및 경영성과'!BJ7 -> 0
B42: U국가 | C42: ='2. 의사결정 및 경영성과'!F7 -> 92.9 | D42: ='2. 의사결정 및 경영성과'!I7 -> 93.4 | E42: ='2. 의사결정 및 경영성과'!L7 -> 94.2 | F42: ='2. 의사결정 및 경영성과'!O7 -> 95 | G42: ='2. 의사결정 및 경영성과'!R7 -> 95.6 | H42: ='2. 의사결정 및 경영성과'!U7 -> 96.2 | I42: ='2. 의사결정 및 경영성과'!X7 -> 97 | J42: ='2. 의사결정 및 경영성과'!AA7 -> 97.5 | K42: ='2. 의사결정 및 경영성과'!AD7 -> 98.1 | L42: ='2. 의사결정 및 경영성과'!AG7 -> 98.8 | M42: ='2. 의사결정 및 경영성과'!AJ7 -> 99.4 | N42: ='2. 의사결정 및 경영성과'!AM7 -> 100 | O42: ='2. 의사결정 및 경영성과'!AP7 -> 0 | P42: ='2. 의사결정 및 경영성과'!AS7 -> 0 | Q42: ='2. 의사결정 및 경영성과'!AV7 -> 0 | R42: ='2. 의사결정 및 경영성과'!AY7 -> 0 | S42: ='2. 의사결정 및 경영성과'!BB7 -> 0 | T42: ='2. 의사결정 및 경영성과'!BE7 -> 0 | U42: ='2. 의사결정 및 경영성과'!BH7 -> 0 | V42: ='2. 의사결정 및 경영성과'!BK7 -> 0
B43: C국가 | C43: ='2. 의사결정 및 경영성과'!G7 -> 90.5 | D43: ='2. 의사결정 및 경영성과'!J7 -> 91.2 | E43: ='2. 의사결정 및 경영성과'!M7 -> 92.1 | F43: ='2. 의사결정 및 경영성과'!P7 -> 93 | G43: ='2. 의사결정 및 경영성과'!S7 -> 94 | H43: ='2. 의사결정 및 경영성과'!V7 -> 94.9 | I43: ='2. 의사결정 및 경영성과'!Y7 -> 95.7 | J43: ='2. 의사결정 및 경영성과'!AB7 -> 96.5 | K43: ='2. 의사결정 및 경영성과'!AE7 -> 97.3 | L43: ='2. 의사결정 및 경영성과'!AH7 -> 98.1 | M43: ='2. 의사결정 및 경영성과'!AK7 -> 99 | N43: ='2. 의사결정 및 경영성과'!AN7 -> 100 | O43: ='2. 의사결정 및 경영성과'!AQ7 -> 0 | P43: ='2. 의사결정 및 경영성과'!AT7 -> 0 | Q43: ='2. 의사결정 및 경영성과'!AW7 -> 0 | R43: ='2. 의사결정 및 경영성과'!AZ7 -> 0 | S43: ='2. 의사결정 및 경영성과'!BC7 -> 0 | T43: ='2. 의사결정 및 경영성과'!BF7 -> 0 | U43: ='2. 의사결정 및 경영성과'!BI7 -> 0 | V43: ='2. 의사결정 및 경영성과'!BL7 -> 0
A44: 환율 | B44: 한국 | C44: 1 | D44: 1 | E44: 1 | F44: 1 | G44: 1 | H44: 1 | I44: 1 | J44: 1 | K44: 1 | L44: 1 | M44: 1 | N44: 1 | O44: ='2. 의사결정 및 경영성과'!AO8 -> 0 | P44: ='2. 의사결정 및 경영성과'!AR8 -> 0 | Q44: ='2. 의사결정 및 경영성과'!AU8 -> 0 | R44: ='2. 의사결정 및 경영성과'!AX8 -> 0 | S44: ='2. 의사결정 및 경영성과'!BA8 -> 0 | T44: ='2. 의사결정 및 경영성과'!BD8 -> 0 | U44: ='2. 의사결정 및 경영성과'!BG8 -> 0 | V44: ='2. 의사결정 및 경영성과'!BJ8 -> 0
B45: U국가 | C45: ='2. 의사결정 및 경영성과'!F8 -> 1050 | D45: ='2. 의사결정 및 경영성과'!I8 -> 1060 | E45: ='2. 의사결정 및 경영성과'!L8 -> 1072 | F45: ='2. 의사결정 및 경영성과'!O8 -> 1080 | G45: ='2. 의사결정 및 경영성과'!R8 -> 1082 | H45: ='2. 의사결정 및 경영성과'!U8 -> 1083 | I45: ='2. 의사결정 및 경영성과'!X8 -> 1090 | J45: ='2. 의사결정 및 경영성과'!AA8 -> 1098 | K45: ='2. 의사결정 및 경영성과'!AD8 -> 1104 | L45: ='2. 의사결정 및 경영성과'!AG8 -> 1106 | M45: ='2. 의사결정 및 경영성과'!AJ8 -> 1102 | N45: ='2. 의사결정 및 경영성과'!AM8 -> 1100 | O45: ='2. 의사결정 및 경영성과'!AP8 -> 0 | P45: ='2. 의사결정 및 경영성과'!AS8 -> 0 | Q45: ='2. 의사결정 및 경영성과'!AV8 -> 0 | R45: ='2. 의사결정 및 경영성과'!AY8 -> 0 | S45: ='2. 의사결정 및 경영성과'!BB8 -> 0 | T45: ='2. 의사결정 및 경영성과'!BE8 -> 0 | U45: ='2. 의사결정 및 경영성과'!BH8 -> 0 | V45: ='2. 의사결정 및 경영성과'!BK8 -> 0
B46: C국가 | C46: ='2. 의사결정 및 경영성과'!G8 -> 199 | D46: ='2. 의사결정 및 경영성과'!J8 -> 197 | E46: ='2. 의사결정 및 경영성과'!M8 -> 195 | F46: ='2. 의사결정 및 경영성과'!P8 -> 193 | G46: ='2. 의사결정 및 경영성과'!S8 -> 189 | H46: ='2. 의사결정 및 경영성과'!V8 -> 188 | I46: ='2. 의사결정 및 경영성과'!Y8 -> 187 | J46: ='2. 의사결정 및 경영성과'!AB8 -> 185 | K46: ='2. 의사결정 및 경영성과'!AE8 -> 179 | L46: ='2. 의사결정 및 경영성과'!AH8 -> 176 | M46: ='2. 의사결정 및 경영성과'!AK8 -> 175.3 | N46: ='2. 의사결정 및 경영성과'!AN8 -> 175 | O46: ='2. 의사결정 및 경영성과'!AQ8 -> 0 | P46: ='2. 의사결정 및 경영성과'!AT8 -> 0 | Q46: ='2. 의사결정 및 경영성과'!AW8 -> 0 | R46: ='2. 의사결정 및 경영성과'!AZ8 -> 0 | S46: ='2. 의사결정 및 경영성과'!BC8 -> 0 | T46: ='2. 의사결정 및 경영성과'!BF8 -> 0 | U46: ='2. 의사결정 및 경영성과'!BI8 -> 0 | V46: ='2. 의사결정 및 경영성과'!BL8 -> 0
A47: 기업별 판매량 | B47: 한국 | C47: ='2. 의사결정 및 경영성과'!E68 -> 38739 | D47: ='2. 의사결정 및 경영성과'!H68 -> 49455 | E47: ='2. 의사결정 및 경영성과'!K68 -> 46095 | F47: ='2. 의사결정 및 경영성과'!N68 -> 53923 | G47: ='2. 의사결정 및 경영성과'!Q68 -> 38959 | H47: ='2. 의사결정 및 경영성과'!T68 -> 59451 | I47: ='2. 의사결정 및 경영성과'!W68 -> 53746 | J47: ='2. 의사결정 및 경영성과'!Z68 -> 73267 | K47: ='2. 의사결정 및 경영성과'!AC68 -> 65552 | L47: ='2. 의사결정 및 경영성과'!AF68 -> 80232 | M47: ='2. 의사결정 및 경영성과'!AI68 -> 69981 | N47: ='2. 의사결정 및 경영성과'!AL68 -> 66680 | O47: ='2. 의사결정 및 경영성과'!AO68 -> 0 | P47: ='2. 의사결정 및 경영성과'!AR68 -> 0 | Q47: ='2. 의사결정 및 경영성과'!AU68 -> 0 | R47: ='2. 의사결정 및 경영성과'!AX68 -> 0 | S47: ='2. 의사결정 및 경영성과'!BA68 -> 0 | T47: ='2. 의사결정 및 경영성과'!BD68 -> 0 | U47: ='2. 의사결정 및 경영성과'!BG68 -> 0 | V47: ='2. 의사결정 및 경영성과'!BJ68 -> 0
B48: U국가 | C48: ='2. 의사결정 및 경영성과'!F68 -> 23963 | D48: ='2. 의사결정 및 경영성과'!I68 -> 32381 | E48: ='2. 의사결정 및 경영성과'!L68 -> 34739 | F48: ='2. 의사결정 및 경영성과'!O68 -> 39025 | G48: ='2. 의사결정 및 경영성과'!R68 -> 34074 | H48: ='2. 의사결정 및 경영성과'!U68 -> 39074 | I48: ='2. 의사결정 및 경영성과'!X68 -> 39354 | J48: ='2. 의사결정 및 경영성과'!AA68 -> 40033 | K48: ='2. 의사결정 및 경영성과'!AD68 -> 33564 | L48: ='2. 의사결정 및 경영성과'!AG68 -> 36277 | M48: ='2. 의사결정 및 경영성과'!AJ68 -> 33702 | N48: ='2. 의사결정 및 경영성과'!AM68 -> 32680 | O48: ='2. 의사결정 및 경영성과'!AP68 -> 0 | P48: ='2. 의사결정 및 경영성과'!AS68 -> 0 | Q48: ='2. 의사결정 및 경영성과'!AV68 -> 0 | R48: ='2. 의사결정 및 경영성과'!AY68 -> 0 | S48: ='2. 의사결정 및 경영성과'!BB68 -> 0 | T48: ='2. 의사결정 및 경영성과'!BE68 -> 0 | U48: ='2. 의사결정 및 경영성과'!BH68 -> 0 | V48: ='2. 의사결정 및 경영성과'!BK68 -> 0
B49: C국가 | C49: ='2. 의사결정 및 경영성과'!G68 -> 5497 | D49: ='2. 의사결정 및 경영성과'!J68 -> 13894 | E49: ='2. 의사결정 및 경영성과'!M68 -> 10568 | F49: ='2. 의사결정 및 경영성과'!P68 -> 13227 | G49: ='2. 의사결정 및 경영성과'!S68 -> 4700 | H49: ='2. 의사결정 및 경영성과'!V68 -> 15478 | I49: ='2. 의사결정 및 경영성과'!Y68 -> 15275 | J49: ='2. 의사결정 및 경영성과'!AB68 -> 21414 | K49: ='2. 의사결정 및 경영성과'!AE68 -> 17504 | L49: ='2. 의사결정 및 경영성과'!AH68 -> 28354 | M49: ='2. 의사결정 및 경영성과'!AK68 -> 28320 | N49: ='2. 의사결정 및 경영성과'!AN68 -> 30500 | O49: ='2. 의사결정 및 경영성과'!AQ68 -> 0 | P49: ='2. 의사결정 및 경영성과'!AT68 -> 0 | Q49: ='2. 의사결정 및 경영성과'!AW68 -> 0 | R49: ='2. 의사결정 및 경영성과'!AZ68 -> 0 | S49: ='2. 의사결정 및 경영성과'!BC68 -> 0 | T49: ='2. 의사결정 및 경영성과'!BF68 -> 0 | U49: ='2. 의사결정 및 경영성과'!BI68 -> 0 | V49: ='2. 의사결정 및 경영성과'!BL68 -> 0
B50: 총합 | C50: =SUM(C47:C49) -> 68199 | D50: =SUM(D47:D49) -> 95730 | E50: =SUM(E47:E49) -> 91402 | F50: =SUM(F47:F49) -> 106175 | G50: =SUM(G47:G49) -> 77733 | H50: =SUM(H47:H49) -> 114003 | I50: =SUM(I47:I49) -> 108375 | J50: =SUM(J47:J49) -> 134714 | ... V50: =SUM(V47:V49) -> 0
A65: 3. GDP 변화와 판매량간의 관계
A81: 4. 계절 변화와 판매량간의 관계
B82: 영업본부 | C82: 1차년도 | G82: 2차년도 | K82: 3차년도 | O82: 4차년도 | S82: 5차년도
C83: 1Q | D83: 2Q | E83: 3Q | F83: 4Q | G83: 1Q | H83: 2Q | I83: 3Q | J83: 4Q | K83: 1Q | L83: 2Q | M83: 3Q | N83: 4Q | O83: 1Q | P83: 2Q | Q83: 3Q | R83: 4Q | S83: 1Q | T83: 2Q | U83: 3Q | V83: 4Q
B84: 한국 판매량 | C84: =C$47 -> 38739 | D84: =D$47 -> 49455 | E84: =E$47 -> 46095 | F84: =F$47 -> 53923 | G84: =G$47 -> 38959 | H84: =H$47 -> 59451 | I84: =I$47 -> 53746 | J84: =J$47 -> 73267 | ... V84: =V$47 -> 0
B85: U국가 판매량 | C85: =C$48 -> 23963 | D85: =D$48 -> 32381 | E85: =E$48 -> 34739 | F85: =F$48 -> 39025 | G85: =G$48 -> 34074 | H85: =H$48 -> 39074 | I85: =I$48 -> 39354 | J85: =J$48 -> 40033 | ... V85: =V$48 -> 0
B86: C국가 판매량 | C86: =C$49 -> 5497 | D86: =D$49 -> 13894 | E86: =E$49 -> 10568 | F86: =F$49 -> 13227 | G86: =G$49 -> 4700 | H86: =H$49 -> 15478 | I86: =I$49 -> 15275 | J86: =J$49 -> 21414 | ... V86: =V$49 -> 0
B87: 총 판매량 | C87: =C$50 -> 68199 | D87: =D$50 -> 95730 | E87: =E$50 -> 91402 | F87: =F$50 -> 106175 | G87: =G$50 -> 77733 | H87: =H$50 -> 114003 | I87: =I$50 -> 108375 | J87: =J$50 -> 134714 | ... V87: =V$50 -> 0
A105: 5. R&D와 제품 모델 및 판매량간의 관계
B106: 영업본부 | C106: 1차년도 | G106: 2차년도 | K106: 3차년도 | O106: 4차년도 | S106: 5차년도
C107: 1Q | D107: 2Q | E107: 3Q | F107: 4Q | G107: 1Q | H107: 2Q | I107: 3Q | J107: 4Q | K107: 1Q | L107: 2Q | M107: 3Q | N107: 4Q | O107: 1Q | P107: 2Q | Q107: 3Q | R107: 4Q | S107: 1Q | T107: 2Q | U107: 3Q | V107: 4Q
B108: ='2. 의사결정 및 경영성과'!$D$37 -> 1. 선행기술R&D투자비 | C108: ='2. 의사결정 및 경영성과'!$E$37 -> 1120000000 | D108: ='2. 의사결정 및 경영성과'!$H$37 -> 1.4e+09 | E108: ='2. 의사결정 및 경영성과'!$E$37 -> 1120000000 | F108: ='2. 의사결정 및 경영성과'!$H$37 -> 1.4e+09 | G108: ='2. 의사결정 및 경영성과'!$E$37 -> 1120000000 | H108: ='2. 의사결정 및 경영성과'!$H$37 -> 1.4e+09 | I108: ='2. 의사결정 및 경영성과'!$E$37 -> 1120000000 | J108: ='2. 의사결정 및 경영성과'!$H$37 -> 1.4e+09 | K108: ='2. 의사결정 및 경영성과'!$E$37 -> 1120000000 | L108: ='2. 의사결정 및 경영성과'!$H$37 -> 1.4e+09 | M108: ='2. 의사결정 및 경영성과'!$E$37 -> 1120000000 | N108: ='2. 의사결정 및 경영성과'!$H$37 -> 1.4e+09 | O108: ='2. 의사결정 및 경영성과'!$E$37 -> 1120000000 | P108: ='2. 의사결정 및 경영성과'!$H$37 -> 1.4e+09 | Q108: ='2. 의사결정 및 경영성과'!$E$37 -> 1120000000 | R108: ='2. 의사결정 및 경영성과'!$H$37 -> 1.4e+09 | S108: ='2. 의사결정 및 경영성과'!$E$37 -> 1120000000 | T108: ='2. 의사결정 및 경영성과'!$H$37 -> 1.4e+09 | U108: ='2. 의사결정 및 경영성과'!$E$37 -> 1120000000 | V108: ='2. 의사결정 및 경영성과'!$H$37 -> 1.4e+09
B109: 판매 모델번호 | C109: ='2. 의사결정 및 경영성과'!E18 -> 1 | D109: ='2. 의사결정 및 경영성과'!H18 -> 1 | E109: ='2. 의사결정 및 경영성과'!K18 -> 1 | F109: ='2. 의사결정 및 경영성과'!N18 -> 1 | G109: ='2. 의사결정 및 경영성과'!Q18 -> 2 | H109: ='2. 의사결정 및 경영성과'!T18 -> 2 | I109: ='2. 의사결정 및 경영성과'!W18 -> 2 | J109: ='2. 의사결정 및 경영성과'!Z18 -> 2 | K109: ='2. 의사결정 및 경영성과'!AC18 -> 3 | L109: ='2. 의사결정 및 경영성과'!AF18 -> 3 | M109: ='2. 의사결정 및 경영성과'!AI18 -> 4 | N109: ='2. 의사결정 및 경영성과'!AL18 -> 4 | O109: ='2. 의사결정 및 경영성과'!AO18 -> 0 | P109: ='2. 의사결정 및 경영성과'!AR18 -> 0 | Q109: ='2. 의사결정 및 경영성과'!AU18 -> 0 | R109: ='2. 의사결정 및 경영성과'!AX18 -> 0 | S109: ='2. 의사결정 및 경영성과'!BA18 -> 0 | T109: ='2. 의사결정 및 경영성과'!BD18 -> 0 | U109: ='2. 의사결정 및 경영성과'!BG18 -> 0 | V109: ='2. 의사결정 및 경영성과'!BJ18 -> 0
B110: 한국 판매량 | C110: =C$47 -> 38739 | D110: =D$47 -> 49455 | E110: =E$47 -> 46095 | F110: =F$47 -> 53923 | G110: =G$47 -> 38959 | H110: =H$47 -> 59451 | I110: =I$47 -> 53746 | J110: =J$47 -> 73267 | ... V110: =V$47 -> 0
B111: U국가 판매량 | C111: =C$48 -> 23963 | D111: =D$48 -> 32381 | E111: =E$48 -> 34739 | F111: =F$48 -> 39025 | G111: =G$48 -> 34074 | H111: =H$48 -> 39074 | I111: =I$48 -> 39354 | J111: =J$48 -> 40033 | ... V111: =V$48 -> 0
...

Sheet 1. Parameter Table
A2: 1. Parameter Table | D2: ▶ 핵심 변수들에 대한 Parameter Table입니다.
A5: ▶ 생산 Parameter | L5: ▶ 마케팅, HR, 재무 Parameter
B7: 1. 라인당 생산량 Table | L7: 14. 영업 본부 임직원 급여 Table
D8: 한국 | F8: U국가 | H8: C국가 | N8: 한국 (원) | O8: U국가 (달러) | P8: C국가 (위안)
C9: 작업시간 | D9: 정규 | E9: 2교대 | F9: 정규 | G9: 2교대 | H9: 정규 | I9: 2교대 | M9: 분기별 지급액 | N9: 800000000 | O9: 900000 | P9: 3000000
C10: 40 | D10: 20000 | E10: 19000 | F10: 21000 | G10: 19950 | H10: 19000 | I10: 18050
C11: 44 | D11: 20800 | E11: 19760 | F11: 21840 | G11: 20748 | H11: 19760 | I11: 18772 | L11: 15. 한국 본사 임직원 급여 Table
C12: 48 | D12: 21600 | E12: 20520 | F12: 22680 | G12: 21546 | H12: 20520 | I12: 19494 | M12: 분기별 지급액 | N12: 3000000000
B14: 2. 라인당 노무비 Table | D14: (정규라인 입력 값에 자동 연동) | L14: 16. 물류비 Table
D15: 한국 (원) | F15: U국가 (달러) | H15: C국가 (위안) | N15: 한국-한국 | O15: 한국-U국가 | P15: 한국-C국가 | Q15: U국가-U국가 | R15: C국가-C국가
C16: 작업시간 | D16: 정규 | E16: 2교대 | F16: 정규 | G16: 2교대 | H16: 정규 | I16: 2교대 | M16: 단위당 물류비 (원) | N16: 10000 | O16: 50000 | P16: 40000 | Q16: 15000 | R16: 10000
C17: 40 | D17: 2000000000 | E17: =D17*1.1 -> 2200000000 | F17: 2200000 | G17: 2420000 | H17: 8000000 | I17: 8800000
C18: 44 | D18: =D17*1.05 -> 2100000000 | E18: =E17*1.05 -> 2310000000 | F18: =F17*1.05 -> 2310000 | G18: =G17*1.05 -> 2541000 | H18: =H17*1.05 -> 8400000 | I18: =I17*1.05 -> 9240000 | L18: 17. 재고관리비 Table
C19: 48 | D19: =D17*1.1 -> 2200000000 | E19: =E17*1.1 -> 2420000000 | F19: =F17*1.1 -> 2420000 | G19: =G17*1.1 -> 2662000 | H19: =H17*1.1 -> 8800000 | I19: =I17*1.1 -> 9680000 | N19: 한국 (원) | O19: U국가 (달러) | P19: C국가 (위안)
M20: 단위당 재고관리비용 | N20: 40000 | O20: 40 | P20: 200
B21: 3. 모델별 재료비 Table
C22: 모델 번호 | D22: 4 | E22: 5 | F22: 6 | G22: 7 | H22: 8 | I22: 9 | L22: 18. 영업본부 관리비 Table
C23: 한국 공장 | D23: 200000 | E23: 225000 | F23: 255000 | G23: 290000 | H23: 315000 | I23: 345000 | N23: 한국 (원) | O23: U국가 (달러) | P23: C국가 (위안)
C24: U국가 공장 | D24: 180 | E24: 200 | F24: 220 | G24: 250 | H24: 280 | I24: 300 | M24: 분기당 | N24: 500000000 | O24: 500000 | P24: 2000000
C25: C국가 공장 | D25: 1000 | E25: 1150 | F25: 1200 | G25: 1380 | H25: 1650 | I25: 1800
L26: 19. 유통 매장관리비 Table
B27: 4. 라인당 Utility 비용 | N27: 한국 (원) | O27: U국가 (달러) | P27: C국가 (위안)
D28: 한국 (원) | F28: U국가 (달러) | H28: C국가 (위안) | M28: 분기 당 | N28: 50000000 | O28: 70000 | P28: 250000
C29: 생산라인 | D29: 정규 | E29: 2교대 | F29: 정규 | G29: 2교대 | H29: 정규 | I29: 2교대
C30: 비용 | D30: 300000000 | E30: 300000000 | F30: 300000 | G30: 300000 | H30: 1300000 | I30: 1300000 | L30: 20. 신규영업사원 채용 및 교육훈련비 Table
N31: 한국 (원) | O31: U국가 (달러) | P31: C국가 (위안)
B32: 5. 공장 인건비 및 기타경비 | M32: 분기당 | N32: 6000000 | O32: 7000 | P32: 30000
D33: 한국 (원) | F33: U국가 (달러) | H33: C국가 (위안)
C34: 생산라인 | D34: 정규 | E34: 2교대 | F34: 정규 | G34: 2교대 | H34: 정규 | I34: 2교대 | L34: 21. 본사 임차료 Table
C35: 공장 인건비 및 기타 경비 | D35: 4000000000 | E35: 0 | F35: 2000000 | G35: 0 | H35: 5000000 | I35: 0 | M35: 한국 본사 (원) | N35: 1000000000
B37: 6. 생산라인 인력 채용 및 훈련 비용 Table (정규 및 2교대 동일) | L37: 22. 제세공과금 비율 Table
D38: 한국 (원) | E38: U국가 (달러) | F38: C국가 (위안) | M38: 제세공과금 비율 | N38: 0.1
C39: 정규 및 2교대 | D39: 500000000 | E39: 500000 | F39: 1500000
L40: 23. 전략적 의사결정 투자 회수 비율 Table
B41: 7. 생산라인 신설비용 Table | M41: 전략적 의사결정 | N41: 신공정 특허 인수 | O41: 유통채널 M&A
D42: 한국 (원) | E42: U국가 (달러) | F42: C국가 (위안) | M42: 기타비용 처리 비율 | N42: 0.3 | O42: 0.3
C43: 정규 생산라인 | D43: 2000000000 | E43: 2000000 | F43: 10000000
L44: 24. 법인세율 Table
B45: 8. 공장 신설비용 Table | N45: 2억 이하 | O45: 2억 초과~200억 이하 | P45: 200억 초과
D46: 한국 (원) | E46: U국가 (달러) | F46: C국가 (위안) | M46: 과세표준 구간 | N46: 200000000 | O46: 20000000000 | P46: 20000000000
...

Sheet 4. 재무분석도구
B2: 손익추정 방법 | D2: (Input) 2 단계. 예측값 및 경제지표 입력 | I2: (Input) 1 단계. 경영의사결정 입력 | O2: (Output) 3단계. 추정 손익계산서 | Z2: 현금 흐름 추정 방법 | AB2: (2). 추정 현금흐름표 | AJ2: (3). 추정 재무상태표 | AP2: (4). 추정 재무비율 | AX2: 참고. 추정 ROE 분석 | BS2: (5) - HR 원가 분석 | CC2: 손익분기 분석
B4: 1단계. CMO, CPO, CTO, CHO, CFO의 의사결정 값을 입력 | K4: 의사결정 입력값 | L4: 추정값 | M4: 자동 계산 | O4: (Output) 손익계산서 추정치 - 자동 계산 | Z4: 1단계. 손익 추정이 먼저 수행되어야 함 | AE4: (Output) 현금흐름표 추정치 | BS4: 1. 인적자원에 활동에서 발행하는 원가 구성요소들을 이해하고, 이를 관리하기 위한 미션입니다. 2. 인적자원 활동과 관련된 주요 의사결정에 따른 HR원가 총합과, 판매량에 따른 단위당 HR원가를 계산해 보십시오. | CC4: 1. 생산 라인의 증설 및 공장 신설에 대한 경제성을 분석하기 위한 미션입니다. 2. 생산 의사결정에 따라서 발생하는 비용을 고정비와 변동비로 나누어 계산한 후 손익분기점(BEP)를 계산해 보십시오. 3. 분석 결과를 타 팀의 예측치와 비교해 보시기 바랍니다.
B5: - 각 의사결정이 입력될 때 실시간으로 입력 | D5: 역할 | E5: 의사결정 및 추정변수 | F5: 한국 | G5: U국가 | H5: C국가 | I5: 역할 | J5: 의사결정 및 추정변수 | K5: 한국 | L5: U국가 | M5: C국가 | O5: 항목 | P5: 예상치 | Q5: 비율 | Z5: - 손익을 추정하면 현금흐름표가 자동으로 완성됨 | AB5: 항목 | AC5: 금액 | AE5: 항목 | AF5: A. 예상치 | AJ5: 항 목 | AK5: 금 액 | AL5: 합 계 | AP5: ▶ 경영 성과와 재무 상태에 따른 재무 비율 분석 | AX5: ▶ ROE를 통한 심층 분석 | BC5: ROE 분석 구조도 | CC5: (Input) 경영 의사결정 입력 및 추정 | CK5: (Output) 생산능력 조정에 따른 경제성 분석
B6: - 혹은 의사결정 값을 복사해서 붙여넣기 | D6: CMO | E6: 1. 판매량 (예측) | F6: 66680 | G6: 32680 | H6: 30500 | I6: CEO 의사결정 화면의 입력 값 | J6: 1. CSR 활동비 | K6: 500000000 | O6: I. 매출액 | P6: =L67 -> 88631620000 | Q6: =P6/$P$6 -> 1 | AB6: I. 영업활동으로 인한 현금흐름 | AC6: =AC7-AC11+AC15-AC16-AC17 -> 2.8823525e+09 | AE6: I. 영업활동 현금 흐름 | AF6: =AC6 -> 2.8823525e+09 | AJ6: Ⅰ. 유동자산 | AL6: =SUM(AK7,AK12) -> 6.433819e+10 | AP6: 구분 | AQ6: 주요 재무비율 | AR6: 구성 요소 | AS6: 금액 | AT6: 비율 | AY6: 구분 | AZ6: 항목 | BA6: A. 예상치 | BS6: 의사결정 | BT6: 한국 | BU6: U국가 | BV6: C국가 | BW6: 합계 | CC6: 역할 | CD6: 주요 의사결정 | CF6: 한국 | CG6: U국가 | CH6: C국가 | CK6: ▶ 경제성 분석 세부내역 (자동계산)
E7: 2. 기말 재고량 (예측) | F7: 18149 | G7: 3528 | H7: 0 | J7: 2. 임직원 인센티브 | K7: 1500000000 | O7: 1. 국내 매출액 | P7: =L68 -> 45342400000 | Q7: =P7/$P$6 -> 0.51158266 | Z7: 2단계. 전기 매출액을 수정 | AB7: 1. 매출 등 수익활동으로부터 유입액 | AC7: =AC9+AC10 -> 88714793496 | AE7: II. 투자활동 현금 흐름 | AF7: =AC18 -> -2030900000 | AJ7: 1. 당좌자산 | AK7: =SUM(AK8:AK11) -> 5.6501456e+10 | AP7: 수익성 | AQ7: 1. 자기자본 이익률 (=순이익/자기자본) | AR7: 순이익 | AS7: =AK34 -> 4.0374031e+09 | AT7: =AS7/AS8 -> 0.054386713 | AX7: (Input) | AY7: 손익계산서 활용 | AZ7: 매출액 | BA7: =P6 -> 88631620000 | BC7: 매출원가 | BF7: 매출액 | BS7: 1. 임직원 급여 | BT7: ='4. 재무분석도구'!P87 -> 2813406000 | BU7: ='4. 재무분석도구'!Q87 -> 732966300 | BV7: ='4. 재무분석도구'!R87 -> 388694250 | BW7: =SUM(BT7:BV7) -> 3935066550 | CC7: CMO | CD7: 1. 판매가격 | CF7: 680000 | CG7: 640 | CH7: 3800 | CK7: 공장 | CL7: 한국 | CN7: U국가 | CP7: C국가
B8: 2단계. CMO, CPO, CTO, CHO의 예측 값 및 경제 지표 입력 | E8: 3. 청산 매출량 (예측) | G8: 0 | H8: 0 | I8: CMO 의사결정 화면의 입력 값 | J8: 1. 판매제품 모델 | K8: 4 | O8: 2. 수출액 | P8: =L71 -> 43289220000 | Q8: =P8/$P$6 -> 0.48841734 | Z8: - 전기 보고서에서 전기 매출액을 셀 X8에 입력 | AB8: (전기 매출액을 입력) | AC8: 88839553740 | AE8: III. 재무활동 현금 흐름 | AF8: =AC29 -> -1.2112209e+08 | AJ8: 가. 현금 및 현금 등가물 | AK8: =AC42 -> 1.4948808e+10 | AR8: 자기자본 | AS8: =AL37 -> 7.42351e+10 | AZ8: 매출총이익 | BA8: =P14 -> 41707834071 | BC8: =P10 -> 46923785929 | BF8: =BA7 -> 88631620000 | BI8: 이익 | BS8: 2. 영업직원 급여 | BT8: ='4. 재무분석도구'!K108 -> 2200000000 | BU8: ='4. 재무분석도구'!K112 -> 1573000000 | BV8: ='4. 재무분석도구'!K116 -> 750750000 | BW8: =SUM(BT8:BV8) -> 4523750000 | CD8: 2. 가격의 마케팅원가 비율(%) | CK8: 라인신설 유형 | CL8: 정규 | CM8: 2교대 | CN8: 정규 | CO8: 2교대 | CP8: 정규 | CQ8: 2교대
B9: - 각 function의 예측 값을 요청 후 입력 | E9: 4. 기초 유통매장 수 | F9: 25 | G9: 13 | H9: 12 | J9: 2. 영업본부의 공장 발주량 | K9: 60000 | L9: 30000 | M9: 30000 | O9: 3. 청산 매출액 | P9: =L78 -> 0 | Q9: =P9/$P$6 -> 0 | AB9: 가. 전기 매출 유입액 (=전기 매출액의 0.4) | AC9: =AC8*P234 -> 35535821496 | AE9: IV. 현금의 증가/손실 (=I+II+III) | AF9: =AF6+AF7+AF8 -> 7.3033043e+08 | AJ9: 나. 매출채권 | AK9: =P6*(1-0.6) -> 35452648000 | AQ9: 2. 매출액 이익율 (= 영업이익/매출액) | AR9: 영업이익 | AS9: =AS7 -> 4.0374031e+09 | AT9: =AS9/AS10 -> 0.045552627 | AZ9: 영업이익 | BA9: =P29 -> 4969493866 | BF9: + | BI9: =P41 -> 4.0374031e+09 | BS9: 3. 임직원 인센티브 | BT9: ='4. 재무분석도구'!P89 -> 7.7021408e+08 | BU9: ='4. 재무분석도구'!Q89 -> 3.7748344e+08 | BV9: ='4. 재무분석도구'!R89 -> 3.5230248e+08 | BW9: =SUM(BT9:BV9) -> 1500000000 | CC9: CPO | CD9: 1. 판매제품 모델 | CF9: 4 | CK9: I. 고정비 총계 | CL9: =SUM(CL10:CL13) -> 3515000000 | CM9: =SUM(CM10:CM13) -> 0 | CN9: =SUM(CN10:CN13) -> #DIV/0! | CO9: =SUM(CO10:CO13) -> 0 | CP9: =SUM(CP10:CP13) -> #DIV/0! | CQ9: =SUM(CQ10:CQ13) -> 0
B10: - 환율, 소비자 물가지수, 이자율 등을 입력 | E10: 5. 기말 유통매장 수 | F10: =K11+F9 -> 30 | G10: =L11+G9 -> 15 | H10: =M11+H9 -> 15 | J10: 3. 판매가격 | K10: 680000 | L10: 640 | M10: 3800 | O10: II. 매출원가 | P10: =L85 -> 46923785929 | Q10: =P10/$P$6 -> 0.52942489 | Z10: 3단계. 기초 현금을 수정 | AB10: 나. 당기 매출 유입액 (=당기 매출액의 0.6) | AC10: =P6*Q234 -> 53178972000 | AE10: V. 기초의 현금 | AF10: =AC40 -> 14218477611 | AJ10: 다. 단기 금융상품 | AK10: =K44 -> 5000000000 | AR10: 매출액 | AS10: 88631620000 | AZ10: 경상이익 | BA10: =P37 -> 5021753866 | BC10: 판관비 | BF10: 영업외 수익 | BI10: / | BL10: 매출액 이익율 | BS10: 4. 영업직원 교육훈련비 | BT10: ='4. 재무분석도구'!P96 -> 610000000 | BU10: ='4. 재무분석도구'!Q96 -> 350900000 | BV10: ='4. 재무분석도구'!R96 -> 290500000 | BW10: =SUM(BT10:BV10) -> 1251400000 | CD10: 2. 신설하는 정규생산라인 수 | CF10: 1 | CG10: 0 | CH10: 0 | CK10: 1. 공장건설비 (감가상각) | CL10: =CM60 -> 400000000 | CN10: =IF(CG14=1,CO60,0) -> 0 | CP10: =IF(CH14=1,CQ55,0) -> 0
D11: CPO | E11: 1. 최종 생산량 (예측) | F11: 136080 | J11: 4. 유통매장 신설 및 폐쇄 | K11: 5 | L11: 2 | M11: 3 | O11: 1. 기초 제품 재고액 | P11: 5564520000 | Q11: =P11/$P$6 -> 0.06278256 | Z11: - 전기 보고서에서 기말현금을 셀 X41에 입력 | AB11: 2. 매입 및 종업원에 대한 유출액 | AC11: =AC12-AC13+AC14 -> 84934340205 | AE11: VI. 기말의 현금 (=IV+V) | AF11: =AF9+AF10 -> 1.4948808e+10 | AJ11: 라. 단기 매매증권(=유가증권의 기말장부가) | AK11: =R249 -> 1100000000 | AP11: 유동성 | AQ11: 3. 당좌 비율 (=당좌자산/유동부채) | AR11: 당좌자산 | AS11: =AK7 -> 5.6501456e+10 | AT11: =IF(AS12=0,"해당 없음",AS11/AS12) -> 해당 없음 | AZ11: 순이익 | BA11: =P41 -> 4.0374031e+09 | BC11: =P15 -> 36738340205 | BF11: =#REF! -> #REF! | BI11: 매출액 | BL11: =BI9/BI12 -> 0.045552627 | BS11: 5. 연구개발비 | BT11: ='4. 재무분석도구'!P97 -> 1.8795791e+09 | BU11: ='4. 재무분석도구'!Q97 -> 9.2118543e+08 | BV11: ='4. 재무분석도구'!R97 -> 8.5973548e+08 | BW11: =SUM(BT11:BV11) -> 3660500000 | CD11: 3. 정규 생산라인의 작업 시간 | CF11: 48 | CG11: 0 | CH11: 0 | CK11: 2. 생산라인 건설비 (감가상각) | CL11: =CM61 -> 100000000 | CN11: =IF(CG10>0,CG10*CO61,0) -> 0 | CP11: =IF(CH10>0,CH10*CQ56,0) -> 0
B12: 3단계. 손익 추정 | E12: 2. 영업본부 입고량 (예측) | F12: =F13 -> 76080 | G12: =SUM(G13:G14) -> 30000 | H12: =H13+H15 -> 30000 | J12: 5. 광고비 | K12: 3200000000 | L12: 1900000 | M12: 12000000 | O12: 2. 당분기 제조원가 | P12: =L87 -> 49196000000 | Q12: =P12/$P$6 -> 0.5550615 | AB12: 가. 총 제조원가 | AC12: =P12 -> 49196000000 | AJ12: 2. 재고자산 | AK12: =SUM(AK13:AK14) -> 7836734071 | AR12: 유동부채 | AS12: =AL21 -> 0 | AY12: 재무상태표 활용 | AZ12: 자산 | BA12: =AL20 -> 7.433819e+10 | BF12: - | BI12: =BF8 -> 88631620000 | BS12: 6. 기타비용 | BT12: ='4. 재무분석도구'!P99 -> 9.8042283e+08 | BU12: ='4. 재무분석도구'!Q99 -> 5.1448677e+08 | BV12: ='4. 재무분석도구'!R99 -> 4.3572205e+08 | BW12: =SUM(BT12:BV12) -> 1930631655 | CD12: 4. 신설하는 2교대 생산라인 수 | CF12: 0 | CG12: 0 | CH12: 0 | CK12: 3. 노무비 | CL12: =CM55 -> 2200000000 | CM12: =CN55 -> 0 | CN12: =CO55 -> 0 | CO12: =CP55 -> 0 | CP12: =CQ55 -> 0 | CQ12: =CR55 -> 0
E13: 한국 공장 출고량 | F13: 76080 | G13: 30000 | H13: 30000 | J13: 6. 매장당 판매촉진비 | K13: 40000000 | L13: 40000 | M13: 150000 | O13: 3. 기말 제품 재고액 | P13: =L88 -> 7836734071 | Q13: =P13/$P$6 -> 0.088419168 | Z13: 4단계. 단기금융상품의 처분 | AB13: 나. 감가상각비 | AC13: =P63+P64 -> 1000000000 | AJ13: 가. 재료재고 | AK13: =K89 -> 0 | AP13: 안정성 | AQ13: 4. 부채비율 (=부채총계/자기자본) | AR13: 부채총계 | AS13: =AL25 -> 0 | AT13: =AS13/AS14 -> 0 | AZ13: 자본 | BA13: =AL37 -> 7.42351e+10 | BC13: 영업외 비용 | BF13: 비용 | BS13: 7. HR원가 총합 | BT13: =SUM(BT7:BT12) -> 9.253622e+09 | BU13: =SUM(BU7:BU12) -> 4.4700219e+09 | BV13: =SUM(BV7:BV12) -> 3.0777043e+09 | BW13: =SUM(BT13:BV13) -> 16801348205 | CD13: 5. 2교대 생산라인의 작업 시간 | CF13: 0 | CG13: 0 | CH13: 0 | CK13: 4. 경비 | CL13: =CM59 -> 815000000 | CM13: =CN59 -> 0 | CN13: =CO59 -> #DIV/0! | CO13: =CP59 -> 0 | CP13: =CQ59 -> #DIV/0! | CQ13: =CR59 -> 0
B14: - 셀 P11의 기초 제품 재고액을 전기 기말 제품 재고액으로 변경 | E14: U국가 공장 출고량 | G14: 0 | I14: CPO 의사결정 화면의 입력 값 | J14: 1. 가동하는 정규 생산라인 수 | K14: 6 | O14: III. 매출 총 이익 | P14: =L97 -> 41707834071 | Q14: =P14/$P$6 -> 0.47057511 | Z14: - 전기에 투자한 양도성예금 증서 투자액을 셀 X20에 입력 | AB14: 다. 판매 및 관리비 | AC14: =P15 -> 36738340205 | AJ14: 나. 제품재고 | AK14: =K93 -> 7836734071 | AR14: 자기자본 | AS14: =AL37 -> 7.42351e+10 | AX14: (Output) | AY14: 1. 자기자본 이익률 (ROE) | AZ14: 순이익 / 자본 | BA14: =BA11/BA13 -> 0.054386713 | BC14: =P33 -> 33990000 | BF14: =BC8+BC11+BC14+BC17 -> 8.4680467e+10 | BL14: * | BS14: 8. 판매량 | BT14: ='4. 재무분석도구'!P101 -> 66680 | BU14: ='4. 재무분석도구'!Q101 -> 32680 | BV14: ='4. 재무분석도구'!R101 -> 30500 | BW14: =SUM(BT14:BV14) -> 129860 | CD14: 6. 공장건설 | CG14: 1 | CH14: 1 | CK14: II. 변동비 총계 | CL14: =CL15+CL16 -> 4320000000 | CM14: =CM15+CM16 -> 0 | CN14: =CN15+CN16 -> 0 | CO14: =CO15+CO16 -> 0 | CP14: =CP15+CP16 -> 0 | CQ14: =CQ15+CQ16 -> 0
B15: - 1~4 단계 결과로 손익, 영업본부 수익, 제조원가 등이 자동 추정됨 | E15: C국가 공장 출고량 | J15: 2. 조업 중지 정규 생산라인 수 | K15: 0 | O15: IV. 판매 및 관리비 | P15: =L98 -> 36738340205 | Q15: =P15/$P$6 -> 0.41450602 | AB15: 3. 이자 수익 유입액 | AC15: =P31 -> 86250000 | AJ15: Ⅱ. 비유동자산 | AL15: =SUM(AK19,AK16) -> 10000000000 | AP15: 활동성 | AQ15: 5. 총자산 회전율 (=매출액/총자산) | AR15: 매출액 | AS15: =P6 -> 88631620000 | AT15: =AS15/AS16 -> 1.1939314 | AY15: 1-1. 매출액 이익률 (영업활동, 수익성) | AZ15: 순이익 / 매출액 | BA15: =BA11/BA7 -> 0.045552627 | BS15: 9. 단위당 HR원가 | BT15: =BT13/BT14 -> 138776.57 | BU15: =BU13/BU14 -> 136781.58 | BV15: =BV13/BV14 -> 100908.34 | BW15: =BW13/BW14 -> 129380.47 | CC15: CTO | CD15: 1. 선행기술 투자비 | CF15: 2800000000 | CK15: 1. 재료비 | CL15: =CM50 -> 4320000000 | CM15: =CN50 -> 0 | CN15: =CO50 -> 0 | CO15: =CP50 -> 0 | CP15: =CQ50 -> 0 | CQ15: =CR50 -> 0
E16: 3. 부품 긴급 구매량 (예측) | F16: 0 | G16: 0 | H16: 0 | J16: 3. 폐쇄하는 정규 생산라인 수 | K16: 0 | O16: 1. 임직원급여 | P16: =L99 -> 3935066550 | Q16: =P16/$P$6 -> 0.044397999 | Z16: 5단계. 단기 차입금 상환 | AB16: 4. 이자 비용 유출액 | AC16: =P34 -> 0 | AJ16: 1. 유형자산 | AK16: =SUM(AK17:AK18) -> 10000000000 | AR16: 총자산 | AS16: =AL38 -> 7.42351e+10 | AY16: 1-2. 자산 회전율 (투자활동, 활동성 ) | AZ16: 매출액 / 자산 | BA16: =BA7/BA12 -> 1.1922757 | BC16: 법인세 | BI16: 매출액 | CD16: 2. 양산R&D 투자비 | CF16: 1500000000 | CK16: 2. 마케팅 비용 | CL16: =CF21*CL18 -> 0 | CM16: =CF22*CM18 -> 0 | CN16: =CG21*CN18 -> 0 | CO16: =CO18*CG22 -> 0 | CP16: =CH21*CP18 -> 0 | CQ16: =CI21*CQ18 -> 0
B17: 4단계. 정보 공유 및 전략 수정 | E17: 4. 부품 기말 재고량 (예측) | F17: 0 | G17: 0 | H17: 0 | J17: 4. 정규 생산라인의 작업 시간 | K17: 48 | O17: 2. 영업직원급여 | P17: =L107 -> 4763750000 | Q17: =P17/$P$6 -> 0.053747748 | Z17: - 전기 유동부채의 단기 차입금을 X37에 입력 | AB17: 5. 법인세의 지급 | AC17: =P40 -> 9.8435077e+08 | AJ17: 가. 공장(=공장의 기말장부가) | AK17: 5200000000 | AP17: 성장성 | AQ17: 6. 매출액 증가율 (=(당기매출액-전기매출액)/전기매출액) | AR17: 당기 매출액 | AS17: =P6 -> 88631620000 | AT17: =(AS17-AS18)/AS18 -> -0.0023405536 | AY17: 1-3. 레버리지 비율 (재무활동, 부채비율) | AZ17: 자산 / 자본 | BA17: =BA12/BA13 -> 1.0013887 | BC17: =P40 -> 9.8435077e+08 | BF17: 유동자산 | BI17: =BI12 -> 88631620000 | CD17: 3. R&D 인건비 | CF17: 90000000 | CK17: 단위당 재료비 | CL17: =CL15/CF21 -> 200000 | CM17: =CM15/CF22 -> #DIV/0! | CN17: =CN15/CG21 -> #DIV/0! | CO17: =CO15/CG22 -> #DIV/0! | CP17: =CP15/CH21 -> #DIV/0! | CQ17: =CQ15/CH22 -> #VALUE!
B18: - 예상 손익 정보를 공유하고, 전략 및 계획 수정 | D18: CTO | E18: 1. 분기 초 R&D인원수 | F18: 50 | J18: 5. 가동하는 2교대 생산라인 수 | K18: 0 | O18: 3. 임직원인센티브 | P18: =L123 -> 1500000000 | Q18: =P18/$P$6 -> 0.016923983 | AB18: II. 투자활동으로 인한 현금흐름 | AC18: =AC19-AC24 -> -2030900000 | AJ18: 나. 생산설비(=생산라인의 기말장부가) | AK18: 4800000000 | AR18: 전기 매출액 | AS18: =AC8 -> 88839553740 | AY18: 2. 영역별 효율성 | BF18: 65299591812 | BI18: / | BL18: 자산회전율 | BO18: ROE | CC18: CHO | CD18: 1. 생산 직원 인건비 (라인당) | CF18: 2000000000 | CG18: 0 | CH18: 0 | CK18: 단위당 마케팅 비용 | CL18: =CF7*CF8 -> 0 | CM18: =CL18 -> 0 | CN18: =CG7*CG20*CG8 -> 0 | CO18: =CN18 -> 0 | CP18: =CH7*CH20*CH8 -> 0 | CQ18: =CP18 -> 0
E19: 2. 예상 자발적 퇴직 R&D인원수 | F19: 5 | J19: 6. 조업 중지 2교대 생산라인 수 | K19: 0 | O19: 4. 광고비 | P19: =L124 -> 7390000000 | Q19: =P19/$P$6 -> 0.083378821 | Z19: 6단계. 현금 흐름 추정 | AB19: 1. 투자활동으로 인한 현금 유입액 | AC19: =AC20+AC21+AC22+AC23 -> 4000000000 | AJ19: 3. 투자자산 | AK19: 0 | AY19: 2-1. 생산/구매 효율성 | AZ19: (매출액-매출원가) / 매출액 | BA19: =BA8/BA7 -> 0.47057511 | BF19: + | BI19: 총자산 | BL19: =BI17/BI20 -> 1.1770531 | BO19: =BI9/BI28 -> 0.054386713 | CC19: 경제지표 | CD19: 1 소비자물가지수 | CF19: 1 | CG19: 1 | CH19: 1 | CK19: 단위당 공헌이익 | CL19: =CF7-CL17-CL18 -> 480000 | CM19: =CF7-CM17-CM18 -> #DIV/0! | CN19: =(CG7*CG20)-CN17-CN18 -> #DIV/0! | CO19: =(CG7*CG20)-CO17-CO18 -> #DIV/0! | CP19: =(CH7*CH20)-CP17-CP18 -> #DIV/0! | CQ19: =(CH7*CH20)-CQ17-CQ18 -> #VALUE!
E20: 3. 비자발적 퇴직 R&D인원수 | F20: 0 | J20: 7. 폐쇄하는 2교대 생산라인 수 | O20: 5. 판매 촉진비 | P20: =L130 -> 2253750000 | Q20: =P20/$P$6 -> 0.025428284 | Z20: - 1~6 단계 결과로 기말 현금이 자동으로 추정됨 | AB20: 가. 단기 금융상품의 처분 (=전기 양도성예금증서 투자액) | AC20: 4000000000 | AJ20: 자산총계 | AL20: =SUM(AL6,AL15) -> 7.433819e+10 | AY20: 2-2. 경영관리 효율성 | AZ20: (매출 총이익-판관비) / 매출총이익 | BA20: =BA9/BA8 -> 0.11915013 | BF20: 비유동자산 | BI20: =BF18+BF21 -> 75299591812 | CD20: 2. 환율 | CF20: 1 | CG20: 1100 | CH20: 175 | CK20: 손익분기점 | CL20: =CL9/CL19 -> 7322.9167 | CM20: =CM9/CM19 -> #DIV/0! | CN20: =CN9/CN19 -> #DIV/0! | CO20: =CO9/CO19 -> #DIV/0! | CP20: =CP9/CP19 -> #DIV/0! | CQ20: =CQ9/CQ19 -> #VALUE!
E21: 4. 분기말 R&D인원수 예측치 | F21: =F18-F19-F20 -> 45 | G21: =G18-G19--G20 -> 0 | H21: =H18-H19-H20 -> 0 | J21: 8. 2교대 생산라인의 작업 시간 | K21: 0 | O21: 6. 물류비 | P21: =L140 -> 3460800000 | Q21: =P21/$P$6 -> 0.039047013 | AB21: 나. 유가 증권의 처분 (=처분하는 펀드 계좌수*전기 주가지수) | AC21: =IF(R245<0,ABS(R246),0) -> 0 | AJ21: Ⅰ. 유동부채 | AL21: =SUM(AK22) -> 0 | AY21: 2-3. 자금관리 효율성 | AZ21: 경상이익 / 영업이익 | BA21: =BA10/BA9 -> 1.0105162 | BF21: 10000000000 | CC21: 자동계산 | CD21: 정규생산라인 표준 생산량 | CF21: =IF(CF11=CC49,CD49*CF10,IF(CF11=CC50,CD50*CF10,IF(CF11=CC51,CD51*CF10,0))) -> 21600 | CG21: =IF(CG11=CC49,CF49*CG10,IF(CG11=CC50,CF50*CG10,IF(CG11=CC51,CF51*CG10,0))) -> 0 | CH21: =IF(CH11=CC49,CH49*CH10,IF(CH11=CC50,CH50*CH10,IF(CH11=CC51,CH51*CH10,0))) -> 0
E22: 1. 분기 초 고급R&D인원수 | F22: 23 | J22: 9. 부품 구매량 | K22: 136080 | O22: 7. 재고관리비 | P22: =L149 -> 881192000 | Q22: =P22/$P$6 -> 0.0099421854 | Z22: 7단계. 정보 공유 및 전략 수정 | AB22: 다. 생산설비의 매각 | AC22: 0 | AJ22: 1. 단기차입금 | AK22: =AC31+AC41 -> 0 | AY22: 2-4. 세금 경쟁력 | AZ22: (경상이익-법인세 비용) / 경상이익 | BA22: =BA11/BA10 -> 0.80398267 | BL22: * | CD22: 2교대 생산라인 표준 생산량 | CF22: =IF(CF15=CC49,CE49*CF14,IF(CF15=CC50,CE50*CF14,IF(CF15=CC51,CE51*CF14,0))) -> 0 | CG22: =IF(CG15=CC49,CG49*CG14,IF(CG15=CC50,CG50*CG14,IF(CG15=CC51,CG51*CG14,0))) -> 0
E23: 2. 예상 자발적 퇴직 고급R&D인원수 | F23: 3 | J23: 10. 설비관리 보전비(라인당) | K23: 50000000 | O23: 8. 영업본부 유지비 | P23: =L156 -> 1400000000 | Q23: =P23/$P$6 -> 0.015795717 | Z23: - 예상 현금 흐름 추정 후. 현금 부족시 조달하고, 여유시 투자 및 상환 | AB23: 라. 공장의 매각 | AC23: 0 | AJ23: Ⅱ. 비유동부채 | AL23: =SUM(AK24) -> 0 | CD23: 정규생산 라인당 노무비 | CF23: =IF(CF11=CC54,CD54,IF(CF11=CC55,CD55,IF(CF11=CC56,CD56,0))) -> 2200000000 | CG23: =IF(CG11=CC54,CF54,IF(CG11=CC55,CF55,IF(CG11=CC56,CF56,0)))*CG20 -> 0 | CH23: =IF(CH11=CC54,CH54,IF(CH11=CC55,CH55,IF(CH11=CC56,CH56,0)))*CH20 -> 0
E24: 3. 비자발적 퇴직 고급R&D인원수 | F24: 0 | J24: 11. 2교대라인 신설 (1분기 소요) | K24: 0 | O24: 9. 유통매장 유지비 | P24: =L160 -> 3311250000 | Q24: =P24/$P$6 -> 0.037359692 | AB24: 2. 투자활동으로 인한 현금 유출액 | AC24: =AC25+AC26+AC27+AC28 -> 6030900000 | AJ24: 1. 사채 | AK24: =AC32 -> 0 | BF24: 부채 | BI24: 총자산 | CD24: 2교대 생산라인당 노무비 | CF24: =IF(CF13=CC54,CE54,IF(CF13=CC55,CE55,IF(CF13=CC56,CE56,0))) -> 0 | CG24: =IF(CG13=CC54,CG54,IF(CG13=CC55,CG55,IF(CG13=CC56,CG56,0)))*CG20 -> 0 | CH24: =IF(CH13=CC54,CI54,IF(CH13=CC55,CI55,IF(CH13=CC56,CI56,0)))*CH20 -> 0
E25: 4. 분기말 고급 R&D인원수 예측치 | F25: =F22-F23-F24 -> 20 | J25: 12. 정규라인 신설 (2분기 소요) | K25: 0 | L25: 0 | M25: 0 | O25: 10. 교육훈련비 | P25: =L167 -> 1251400000 | Q25: =P25/$P$6 -> 0.014119115 | AB25: 가. 단기 금융상품의 취득 (=당기 양도성예금중서 투자액) | AC25: =K44 -> 5000000000 | AJ25: 부채총계 | AL25: =SUM(AL21,AL23) -> 0 | BF25: =AL25 -> 0 | BI25: =BF25+BF28 -> 7.42351e+10
D26: CHO | E26: 1. 분기 초 영업직원 수 | F26: 275 | G26: 142 | H26: 145 | J26: 13. 공장의 신설(2분기 소요) 및 폐쇄 | L26: 0 | M26: 0 | O26: 11. 연구개발비 | P26: =L179 -> 3660500000 | Q26: =P26/$P$6 -> 0.041300159 | AB26: 나. 유가 증권의 취득 (=취득하는 펀드 계좌수*전기 주가지수) | AC26: =IF(R245>0,R246,0) -> 1030900000 | AJ26: Ⅰ. 자본금 | AL26: 25000000000 | BF26: + | BI26: / | BL26: 레버리지 비율 | CC26: ▶ 생산능력 조정에 따른 투자비용 증감분
E27: 2. 예상 자발적 퇴직 영업직원 수(-로 입력) | F27: -25 | G27: -12 | H27: -15 | I27: CTO 의사결정 화면의 입력 값 | J27: 1. 선행기술 투자비 | K27: 2800000000 | O27: 12. 본사임차료 | P27: =L189 -> 1000000000 | Q27: =P27/$P$6 -> 0.011282655 | AB27: 다. 생산설비의 취득 | AC27: =IF(K25>=1,K25*Q190*#REF!/Q193)+IF(L25>=1,L25*R190*G38*#REF!/Q193)+IF(M25>=1,M25*S190*H38*#REF!/Q193) -> 0 | AJ27: Ⅱ. 자본 잉여금 | AL27: =SUM(AK28:AK28) -> 0 | BF27: 자기자본 | BI27: 자기자본 | BL27: =BI25/BI28 -> 1 | CD27: 한국 | CF27: U국가 | CH27: C국가
E28: 3. 비자발적 퇴직 영업직원수 | F28: =ABS(F27+(IF(K32<0,K32))) -> 25 | G28: =ABS(G27+(IF(L32<0,L32))) -> 12 | H28: =ABS(H27+(IF(M32<0,M32))) -> 15 | J28: 2. 양산R&D 투자비 | K28: 1200000000 | O28: 13. 기타비용 | P28: =L190 -> 1930631655 | Q28: =P28/$P$6 -> 0.021782651 | AB28: 라. 공장의 취득 | AC28: =IF(L34=1,R195*G29*G28/Q197)+IF(M34=1,S195*H29*H28/Q197) -> 0 | AJ28: 1. 전기말 자본 잉여금 | AK28: 0 | BF28: =BA13 -> 7.42351e+10 | BI28: =BF28 -> 7.42351e+10 | CC28: 1.공장신설 | CF28: =CG14 -> 1 | CH28: =CH14 -> 1
E29: 4. 활동중인 영업직원수 예측치 | F29: =F26+F27-F28 -> 225 | G29: =G26+G27-G28 -> 118 | H29: =H26+H27-H28 -> 115 | J29: 3. R&D인원수 채용(+) 및 해고 (-) | K29: 5 | O29: V. 영업이익 | P29: =P14-P15 -> 4969493866 | Q29: =P29/$P$6 -> 0.056069085 | AB29: III. 재무활동으로 인한 현금흐름 | AC29: =AC30-AC35 -> -1.2112209e+08 | AJ29: 2. 당기 자본 잉여금 증가 | AK29: =AK30*AK31 -> 0 | CC29: 2.라인 신설 | CD29: 정규라인 | CE29: 2교대 라인 | CF29: 정규라인 | CG29: 2교대 라인 | CH29: 정규라인 | CI29: 2교대 라인
E30: 5. 교육 훈련 중인 영업직원 수 | F30: =K32 -> 35 | G30: =L32 -> 17 | H30: =M32 -> 22 | J30: 4. R&D고급인력 스카우트(+) 및 해고 (-) | K30: 3 | O30: VI. 영업외 수익 | P30: =L205 -> 86250000 | Q30: =P30/$P$6 -> 0.000973129 | AB30: 1. 재무활동으로 인한 현금 유입액 | AC30: =SUM(AC31:AC33) -> 0 | AJ30: 2-2. 전기 주가-액면가 | AK30: 774 | CD30: =CF10 -> 1 | CE30: =CF12 -> 0 | CF30: =CG10 -> 0 | CG30: =CG12 -> 0 | CH30: =CH10 -> 0 | CI30: =CH12 -> 0
E31: 6. 분기 초 디지털마케팅 고급인력 | F31: 17 | J31: 5. R&D 인건비 | K31: 9000000 | O31: 1. 이자 수익 | P31: =K206 -> 86250000 | Q31: =P31/$P$6 -> 0.000973129 | AB31: 가. 단기 차입금의 차입(=CFO의 은행대출 의사결정) | AC31: =K41 -> 0 | AJ31: Ⅲ. 이익 잉여금 | AL31: =SUM(AK32:AK33) -> 4.92351e+10 | CC31: 3.작업 시간 | CD31: =CF11 -> 48 | CE31: =CF13 -> 0 | CF31: =CG11 -> 0 | CG31: =CG13 -> 0 | CH31: =CH11 -> 0 | CI31: =CH13 -> 0
E32: 7. 예상 자발적 퇴직 디지털마케팅 고급인력(-로 입력) | F32: 2 | I32: CHO 의사결정 화면의 입력 값 | J32: 1. 영업직원 채용(+) 및 해고(-) | K32: 35 | L32: 17 | M32: 22 | O32: 2. 유가증권 평가 이익 | P32: =IF(R250>0,R250,0) -> 0 | Q32: =P32/$P$6 -> 0 | AB32: 나. 사채의 발행 (=당기 회사채 발행금액) | AC32: =K42 -> 0 | AJ32: 1. 전기 이익 잉여금 | AK32: 45318819107 | CC32: 4.투자비용 | CD32: =SUM(CD33:CD35) -> 2500000000 | CE32: =SUM(CE33:CE35) -> 0 | CF32: =SUM(CF33:CF35) -> 11000000000 | CG32: =SUM(CG33:CG35) -> 0 | CH32: =SUM(CH33:CH35) -> 5250000000 | CI32: =CH13 -> 0
E33: 8. 비자발적 퇴직 디지털마케팅 고급인력 | F33: 0 | J33: 2. 디지털마케팅 고급인력(스카우트 및 해고) | K33: 5 | L33: 0 | M33: 0 | O33: VII. 영업외 비용 | P33: =L208 -> 33990000 | Q33: =P33/$P$6 -> 0.00038349745 | AB33: 다. 주식의 발행 (=당기 발행 주식수*전기 주가) | AC33: =K43*AC34 -> 0 | AJ33: 2. 당기 이익 잉여금 증가 | AK33: =AK34-AK35 -> 3.916281e+09 | CC33: 4.1.공장신설비 | CF33: =IF(CF28=1,CF72*CG20) -> 11000000000 | CH33: =IF(CH28=1,CG72*CH20) -> 5250000000
E34: 9. 분기말 디지털마케팅 고급인력 예측치 | F34: 15 | J34: 3. 영업직원 기본급(인당) | K34: 8000000 | L34: 10000 | M34: 30000 | O34: 1. 이자비용 | P34: =K41*F40*0.25+K42*F41*0.25 -> 0 | Q34: =P34/$P$6 -> 0 | AB34: (전기 주가) | AC34: 5774 | AJ34: 2-1. 당기순이익 | AK34: =P41 -> 4.0374031e+09 | CC34: 4.2.라인신설비 | CD34: =IF(CD30>=1,CD30*CE70) -> 2000000000 | CF34: =IF(CF30>=1,CF30*CF70*CG20) -> FALSE | CH34: =IF(CH30>=1,CH30*CG70*CH20) -> FALSE
J35: 4. 영업직원 복리후생비(인당) | K35: 800000 | L35: 1000 | M35: 3000 | O35: 2. 유가증권 평가 손실 | P35: =IF(R250<0,ABS(R250),0) -> 33990000 | Q35: =P35/$P$6 -> 0.00038349745 | AB35: 2. 재무활동으로 인한 현금 유출액 | AC35: =SUM(AC36:AC38) -> 1.2112209e+08 | AJ35: 2-2. 배당금 | AK35: =IF(AK34>0,AK34*K46,0) -> 1.2112209e+08 | CC35: 4.3.교육훈련비 (손익계산서) | CD35: =IF(CD30>=1,CD30*CE68) -> 500000000 | CE35: =IF(CE30>=1,CE30*CE68) -> FALSE | CF35: =IF(CF30>=1,CF30*CF68*CG20) -> FALSE | CG35: =IF(CG30>=1,CG30*CF68*CG20) -> FALSE | CH35: =IF(CH30>=1,CH30*CG68*CH20) -> FALSE | CI35: =IF(CI30>=1,CI30*CG68*CH20) -> FALSE
D36: CFO | E36: 1. 누적 펀드계좌 수 | F36: 1000000 | J36: 5. 생산직원 기본급(라인당) | K36: 1800000000 | O36: 3. 유형자산 처분 손실 | P36: 0 | Q36: =P36/$P$6 -> 0 | AB36: 가. 단기 차입금 및 긴급자금대출 상환 | AC36: 0 | AJ36: Ⅳ. 자본 조정 | AL36: 0 | CC36: 5.생산증가량 | CD36: =IF(CD31=CC49,CD49*CD30,IF(CD31=CC50,CD50*CD30,IF(CD31=CC51,CD51*CD30))) -> 21600 | CE36: =IF(CE31=CC49,CE49*CE30,IF(CE31=CC50,CE50*CE30,IF(CE31=CC51,CE51*CE30))) -> FALSE | CF36: =IF(CF31=CC49,CF49*CF30,IF(CF31=CC50,CF50*CF30,IF(CF31=CC51,CF51*CF30))) -> FALSE | CG36: =IF(CG31=CC49,CG49*CG30,IF(CG31=CC50,CG50*CG30,IF(CG31=CC51,CG51*CG30))) -> FALSE | CH36: =IF(CH31=CC49,CH49*CH30,IF(CH31=CC50,CH50*CH30,IF(CH31=CC51,CH51*CH30))) -> FALSE | CI36: =IF(CI31=CC49,CI49*CI30,IF(CI31=CC50,CI50*CI30,IF(CI31=CC51,CI51*CI30))) -> FALSE
D37: 경제 동향 | E37: 1 소비자물가지수 (예측) | F37: 1 | G37: 1 | H37: 1 | J37: 6. 생산직원 복리후생비(라인당) | K37: 200000000 | O37: VIII. 경상이익 | P37: =L212 -> 5021753866 | Q37: =P37/$P$6 -> 0.056658717 | AB37: 나. 사채의 상환 (=회사채 발행 시 4분기 후 자동상환) | AC37: 0 | AJ37: 자본 총계 | AL37: =SUM(AL26,AL27,AL31,AL36) -> 7.42351e+10
E38: 2. 환율 (예측) | F38: 1 | G38: 1100 | H38: 175 | J38: 7. 영업직원 교육훈련비(영업본부별) | K38: 400000000 | L38: 200000 | M38: 1000000 | O38: IX. 중단 사업 손익 | P38: =L213 -> 0 | Q38: =P38/$P$6 -> 0 | AB38: 다. 배당금 지급 | AC38: =IF(P41>=1,P41*K46,0) -> 1.2112209e+08 | AJ38: 부채와 자본 총계 | AL38: =SUM(AL25,AL37) -> 7.42351e+10
E39: 3. 양도성예금증서 이자율 (예측) | F39: 0.069 | J39: 8. 생산직원 교육훈련비(라인당) | K39: 80000000 | O39: X. 법인세비용 차감전 순이익 | P39: =L214 -> 5021753866 | Q39: =P39/$P$6 -> 0.056658717 | AB39: IV. 현금의 증가/감소 | AC39: =AC6+AC18+AC29 -> 7.3033043e+08 | AJ39: ※자산총계와 부채와 자본 총계의 불일치 시 이익잉여금으로 조정함 | CH39: 아래는 세부 계산 내역이니 입력하지 마십시오.
E40: 4. 은행대출 이자율 (예측) | F40: 0.0719 | J40: 9. R&D 교육훈련비 | K40: 100000000 | O40: XI. 법인세 비용 | P40: =L215 -> 9.8435077e+08 | Q40: =P40/$P$6 -> 0.01110609 | AB40: V. 기초의 현금 | AC40: 14218477611
E41: 5. 회사채 이자율 (예측) | F41: 0.0794 | I41: CFO 의사결정 화면의 입력 값 | J41: 1. 은행 대출 | K41: 0 | O41: ⅩII. 당기 순이익 | P41: =L216 -> 4.0374031e+09 | Q41: =P41/$P$6 -> 0.045552627 | AB41: Ⅵ. 긴급자금대출 (=현금부족 시 자동대출) | AC41: =IF(AC39+AC40<0,ABS(AC39+AC40),0) -> 0
E42: 6. 전기 한국 주가지수 | F42: 103.09 | J42: 2. 회사채 발행 | K42: 0 | O42: 36638329500 | P42: =P15 -> 36738340205 | Q42: =P42-O42 -> 100010705 | AB42: VII. 기말의 현금 | AC42: =AC39+AC40+AC41 -> 1.4948808e+10
...

Sheet 5. 경제성 분석 도구
D2: 경제성 분석 (1) - BEP 분석 | X2: 경제성 분석(2) - NPV 분석 | AJ2: 경제성 분석 (3) - IRR 분석 | AV2: 경제성 분석 (4) - EVA 분석 | BQ2: 경제성 분석 (5). 생산성 분석
D4: 1. 매출액과 비용이 일치하는 점, 즉 이익이 ‘0’이 되는 손익분기점을 찾아서 매출액, 비용, 이익 간의 관계를 분석하는 기법입니다. 2. 가격, 고정비, 변동비, 생산량을 입력한 후 이익이 0이 되는 생산량의 지점을 찾아보시기 바랍니다. | X4: 1. 프로젝트 수행 시 투자로부터 기대되는 미래 현금유입의 현재가치와 현금유출의 현재가치를 비교하여 투자안의 경제성을 평가하는 기법입니다. 2. 자본 조달 비용과 각 투자안들의 예상되는 현금흐름을 입력한 후 NPV를 추정해 보시기 바랍니다. | AJ4: 1. 프로젝트 수행 시 투자로부터 기대되는 현금유입의 현재가치와 현금유출의 현재가치를 같게 하는 할인율을 계산해 투자의사결정을 하는 기법입니다. 2. 자본 조달 비용과 각 투자안들의 예상되는 현금흐름을 입력한 후 IRR을 추정해 보시기 바랍니다. | AV4: 1. 세후 영업이익에서 자본비용을 차감한 경제적 부가가치를 이용하여 기업이 고유의 영업활동을 통해 창출한 순가치 증가분을 계산하는 기법입니다. 2. 세후 영업이익의 주요 지표와 자본비용의 주요 지표를 입력한 후 EVA를 계산해 보시기 바랍니다. | BQ4: 1. 경영활동을 위해 투입된 요소들에 대해 얼마나 효율적으로 성과를 창출하고 있는가를 측정하는 분석 방법입니다. 2. 재무지표를 활용해 부가가치를 계산한 후 생산성을 분석해 보시기 바랍니다.
